Watching for file changes with StatReloader
Exception in thread django-main-thread:
Traceback (most recent call last):
  File "/usr/lib/python3.10/threading.py", line 1016, in _bootstrap_inner
    self.run()
  File "/usr/lib/python3.10/threading.py", line 953, in run
    self._target(*self._args, **self._kwargs)
  File "/home/ubuntu/.local/lib/python3.10/site-packages/django/utils/autoreload.py", line 64, in wrapper
    fn(*args, **kwargs)
  File "/home/ubuntu/.local/lib/python3.10/site-packages/django/core/management/commands/runserver.py", line 133, in inner_run
    self.check(display_num_errors=True)
  File "/home/ubuntu/.local/lib/python3.10/site-packages/django/core/management/base.py", line 485, in check
    all_issues = checks.run_checks(
  File "/home/ubuntu/.local/lib/python3.10/site-packages/django/core/checks/registry.py", line 88, in run_checks
    new_errors = check(app_configs=app_configs, databases=databases)
  File "/home/ubuntu/.local/lib/python3.10/site-packages/django/core/checks/urls.py", line 14, in check_url_config
    return check_resolver(resolver)
  File "/home/ubuntu/.local/lib/python3.10/site-packages/django/core/checks/urls.py", line 24, in check_resolver
    return check_method()
  File "/home/ubuntu/.local/lib/python3.10/site-packages/django/urls/resolvers.py", line 516, in check
    for pattern in self.url_patterns:
  File "/home/ubuntu/.local/lib/python3.10/site-packages/django/utils/functional.py", line 47, in __get__
    res = instance.__dict__[self.name] = self.func(instance)
  File "/home/ubuntu/.local/lib/python3.10/site-packages/django/urls/resolvers.py", line 735, in url_patterns
    patterns = getattr(self.urlconf_module, "urlpatterns", self.urlconf_module)
  File "/home/ubuntu/.local/lib/python3.10/site-packages/django/utils/functional.py", line 47, in __get__
    res = instance.__dict__[self.name] = self.func(instance)
  File "/home/ubuntu/.local/lib/python3.10/site-packages/django/urls/resolvers.py", line 728, in urlconf_module
    return import_module(self.urlconf_name)
  File "/usr/lib/python3.10/importlib/__init__.py", line 126, in import_module
    return _bootstrap._gcd_import(name[level:], package, level)
  File "<frozen importlib._bootstrap>", line 1050, in _gcd_import
  File "<frozen importlib._bootstrap>", line 1027, in _find_and_load
  File "<frozen importlib._bootstrap>", line 1006, in _find_and_load_unlocked
  File "<frozen importlib._bootstrap>", line 688, in _load_unlocked
  File "<frozen importlib._bootstrap_external>", line 883, in exec_module
  File "<frozen importlib._bootstrap>", line 241, in _call_with_frames_removed
  File "/home/ubuntu/djangobackend/djangobackend/urls.py", line 19, in <module>
    from database.views import add_link
ImportError: cannot import name 'add_link' from 'database.views' (/home/ubuntu/djangobackend/database/views.py)
/home/ubuntu/djangobackend/djangobackend/urls.py changed, reloading.
Performing system checks...

Watching for file changes with StatReloader
Watching for file changes with StatReloader
Error: That port is already in use.
Internal Server Error: /
Traceback (most recent call last):
  File "/home/ubuntu/.local/lib/python3.10/site-packages/django/db/backends/utils.py", line 105, in _execute
    return self.cursor.execute(sql, params)
  File "/home/ubuntu/.local/lib/python3.10/site-packages/django/db/backends/sqlite3/base.py", line 328, in execute
    return super().execute(query, params)
sqlite3.OperationalError: no such table: database_links

The above exception was the direct cause of the following exception:

Traceback (most recent call last):
  File "/home/ubuntu/.local/lib/python3.10/site-packages/django/core/handlers/exception.py", line 55, in inner
    response = get_response(request)
  File "/home/ubuntu/.local/lib/python3.10/site-packages/django/core/handlers/base.py", line 197, in _get_response
    response = wrapped_callback(request, *callback_args, **callback_kwargs)
  File "/home/ubuntu/.local/lib/python3.10/site-packages/django/views/decorators/csrf.py", line 65, in _view_wrapper
    return view_func(request, *args, **kwargs)
  File "/home/ubuntu/.local/lib/python3.10/site-packages/django/views/generic/base.py", line 104, in view
    return self.dispatch(request, *args, **kwargs)
  File "/home/ubuntu/.local/lib/python3.10/site-packages/rest_framework/views.py", line 509, in dispatch
    response = self.handle_exception(exc)
  File "/home/ubuntu/.local/lib/python3.10/site-packages/rest_framework/views.py", line 469, in handle_exception
    self.raise_uncaught_exception(exc)
  File "/home/ubuntu/.local/lib/python3.10/site-packages/rest_framework/views.py", line 480, in raise_uncaught_exception
    raise exc
  File "/home/ubuntu/.local/lib/python3.10/site-packages/rest_framework/views.py", line 506, in dispatch
    response = handler(request, *args, **kwargs)
  File "/home/ubuntu/.local/lib/python3.10/site-packages/rest_framework/decorators.py", line 50, in handler
    return func(*args, **kwargs)
  File "/home/ubuntu/djangobackend/database/views.py", line 13, in getData
    return Response(serializer.data)
  File "/home/ubuntu/.local/lib/python3.10/site-packages/rest_framework/serializers.py", line 768, in data
    ret = super().data
  File "/home/ubuntu/.local/lib/python3.10/site-packages/rest_framework/serializers.py", line 253, in data
    self._data = self.to_representation(self.instance)
  File "/home/ubuntu/.local/lib/python3.10/site-packages/rest_framework/serializers.py", line 686, in to_representation
    return [
  File "/home/ubuntu/.local/lib/python3.10/site-packages/django/db/models/query.py", line 398, in __iter__
    self._fetch_all()
  File "/home/ubuntu/.local/lib/python3.10/site-packages/django/db/models/query.py", line 1926, in _fetch_all
    self._result_cache = list(self._iterable_class(self))
  File "/home/ubuntu/.local/lib/python3.10/site-packages/django/db/models/query.py", line 91, in __iter__
    results = compiler.execute_sql(
  File "/home/ubuntu/.local/lib/python3.10/site-packages/django/db/models/sql/compiler.py", line 1562, in execute_sql
    cursor.execute(sql, params)
  File "/home/ubuntu/.local/lib/python3.10/site-packages/django/db/backends/utils.py", line 122, in execute
    return super().execute(sql, params)
  File "/home/ubuntu/.local/lib/python3.10/site-packages/django/db/backends/utils.py", line 79, in execute
    return self._execute_with_wrappers(
  File "/home/ubuntu/.local/lib/python3.10/site-packages/django/db/backends/utils.py", line 92, in _execute_with_wrappers
    return executor(sql, params, many, context)
  File "/home/ubuntu/.local/lib/python3.10/site-packages/django/db/backends/utils.py", line 100, in _execute
    with self.db.wrap_database_errors:
  File "/home/ubuntu/.local/lib/python3.10/site-packages/django/db/utils.py", line 91, in __exit__
    raise dj_exc_value.with_traceback(traceback) from exc_value
  File "/home/ubuntu/.local/lib/python3.10/site-packages/django/db/backends/utils.py", line 105, in _execute
    return self.cursor.execute(sql, params)
  File "/home/ubuntu/.local/lib/python3.10/site-packages/django/db/backends/sqlite3/base.py", line 328, in execute
    return super().execute(query, params)
django.db.utils.OperationalError: no such table: database_links
[05/Mar/2024 01:45:55] "GET / HTTP/1.1" 500 166447
Not Found: /favicon.ico
[05/Mar/2024 01:45:56] "GET /favicon.ico HTTP/1.1" 404 2764
Watching for file changes with StatReloader
Internal Server Error: /
Traceback (most recent call last):
  File "/home/ubuntu/.local/lib/python3.10/site-packages/django/db/backends/utils.py", line 105, in _execute
    return self.cursor.execute(sql, params)
  File "/home/ubuntu/.local/lib/python3.10/site-packages/django/db/backends/sqlite3/base.py", line 328, in execute
    return super().execute(query, params)
sqlite3.OperationalError: no such table: database_links

The above exception was the direct cause of the following exception:

Traceback (most recent call last):
  File "/home/ubuntu/.local/lib/python3.10/site-packages/django/core/handlers/exception.py", line 55, in inner
    response = get_response(request)
  File "/home/ubuntu/.local/lib/python3.10/site-packages/django/core/handlers/base.py", line 197, in _get_response
    response = wrapped_callback(request, *callback_args, **callback_kwargs)
  File "/home/ubuntu/.local/lib/python3.10/site-packages/django/views/decorators/csrf.py", line 65, in _view_wrapper
    return view_func(request, *args, **kwargs)
  File "/home/ubuntu/.local/lib/python3.10/site-packages/django/views/generic/base.py", line 104, in view
    return self.dispatch(request, *args, **kwargs)
  File "/home/ubuntu/.local/lib/python3.10/site-packages/rest_framework/views.py", line 509, in dispatch
    response = self.handle_exception(exc)
  File "/home/ubuntu/.local/lib/python3.10/site-packages/rest_framework/views.py", line 469, in handle_exception
    self.raise_uncaught_exception(exc)
  File "/home/ubuntu/.local/lib/python3.10/site-packages/rest_framework/views.py", line 480, in raise_uncaught_exception
    raise exc
  File "/home/ubuntu/.local/lib/python3.10/site-packages/rest_framework/views.py", line 506, in dispatch
    response = handler(request, *args, **kwargs)
  File "/home/ubuntu/.local/lib/python3.10/site-packages/rest_framework/decorators.py", line 50, in handler
    return func(*args, **kwargs)
  File "/home/ubuntu/djangobackend/database/views.py", line 13, in getData
    return Response(serializer.data)
  File "/home/ubuntu/.local/lib/python3.10/site-packages/rest_framework/serializers.py", line 768, in data
    ret = super().data
  File "/home/ubuntu/.local/lib/python3.10/site-packages/rest_framework/serializers.py", line 253, in data
    self._data = self.to_representation(self.instance)
  File "/home/ubuntu/.local/lib/python3.10/site-packages/rest_framework/serializers.py", line 686, in to_representation
    return [
  File "/home/ubuntu/.local/lib/python3.10/site-packages/django/db/models/query.py", line 398, in __iter__
    self._fetch_all()
  File "/home/ubuntu/.local/lib/python3.10/site-packages/django/db/models/query.py", line 1926, in _fetch_all
    self._result_cache = list(self._iterable_class(self))
  File "/home/ubuntu/.local/lib/python3.10/site-packages/django/db/models/query.py", line 91, in __iter__
    results = compiler.execute_sql(
  File "/home/ubuntu/.local/lib/python3.10/site-packages/django/db/models/sql/compiler.py", line 1562, in execute_sql
    cursor.execute(sql, params)
  File "/home/ubuntu/.local/lib/python3.10/site-packages/django/db/backends/utils.py", line 122, in execute
    return super().execute(sql, params)
  File "/home/ubuntu/.local/lib/python3.10/site-packages/django/db/backends/utils.py", line 79, in execute
    return self._execute_with_wrappers(
  File "/home/ubuntu/.local/lib/python3.10/site-packages/django/db/backends/utils.py", line 92, in _execute_with_wrappers
    return executor(sql, params, many, context)
  File "/home/ubuntu/.local/lib/python3.10/site-packages/django/db/backends/utils.py", line 100, in _execute
    with self.db.wrap_database_errors:
  File "/home/ubuntu/.local/lib/python3.10/site-packages/django/db/utils.py", line 91, in __exit__
    raise dj_exc_value.with_traceback(traceback) from exc_value
  File "/home/ubuntu/.local/lib/python3.10/site-packages/django/db/backends/utils.py", line 105, in _execute
    return self.cursor.execute(sql, params)
  File "/home/ubuntu/.local/lib/python3.10/site-packages/django/db/backends/sqlite3/base.py", line 328, in execute
    return super().execute(query, params)
django.db.utils.OperationalError: no such table: database_links
[05/Mar/2024 01:50:36] "GET / HTTP/1.1" 500 166447
[05/Mar/2024 01:50:51] "GET /admin HTTP/1.1" 301 0
[05/Mar/2024 01:50:51] "GET /admin/ HTTP/1.1" 302 0
[05/Mar/2024 01:50:51] "GET /admin/login/?next=/admin/ HTTP/1.1" 200 4158
[05/Mar/2024 01:50:51] "GET /static/admin/css/base.css HTTP/1.1" 200 21544
[05/Mar/2024 01:50:51] "GET /static/admin/css/dark_mode.css HTTP/1.1" 200 2682
[05/Mar/2024 01:50:51] "GET /static/admin/css/login.css HTTP/1.1" 200 958
[05/Mar/2024 01:50:51] "GET /static/admin/css/nav_sidebar.css HTTP/1.1" 200 2810
[05/Mar/2024 01:50:51] "GET /static/admin/js/theme.js HTTP/1.1" 200 1943
[05/Mar/2024 01:50:51] "GET /static/admin/js/nav_sidebar.js HTTP/1.1" 200 3063
[05/Mar/2024 01:50:51] "GET /static/admin/css/responsive.css HTTP/1.1" 200 17905
[05/Mar/2024 01:51:25] "POST /admin/login/?next=/admin/ HTTP/1.1" 200 4322
[05/Mar/2024 01:51:33] "POST /admin/login/?next=/admin/ HTTP/1.1" 200 4317
[05/Mar/2024 01:51:41] "POST /admin/login/?next=/admin/ HTTP/1.1" 200 4319
Watching for file changes with StatReloader
[05/Mar/2024 01:54:12] "GET /admin/login/?next=/admin/ HTTP/1.1" 200 4158
[05/Mar/2024 01:54:17] "POST /admin/login/?next=/admin/ HTTP/1.1" 302 0
[05/Mar/2024 01:54:17] "GET /admin/ HTTP/1.1" 200 6191
[05/Mar/2024 01:54:17] "GET /static/admin/css/dashboard.css HTTP/1.1" 200 441
[05/Mar/2024 01:54:17] "GET /static/admin/img/icon-addlink.svg HTTP/1.1" 200 331
[05/Mar/2024 01:54:17] "GET /static/admin/img/icon-changelink.svg HTTP/1.1" 200 380
[05/Mar/2024 01:54:20] "GET /admin/database/links/ HTTP/1.1" 200 7432
[05/Mar/2024 01:54:20] "GET /static/admin/css/changelists.css HTTP/1.1" 200 6811
[05/Mar/2024 01:54:20] "GET /admin/jsi18n/ HTTP/1.1" 200 3342
[05/Mar/2024 01:54:20] "GET /static/admin/js/jquery.init.js HTTP/1.1" 200 347
[05/Mar/2024 01:54:20] "GET /static/admin/js/core.js HTTP/1.1" 200 6208
[05/Mar/2024 01:54:20] "GET /static/admin/js/admin/RelatedObjectLookups.js HTTP/1.1" 200 9042
[05/Mar/2024 01:54:20] "GET /static/admin/js/actions.js HTTP/1.1" 200 8067
[05/Mar/2024 01:54:20] "GET /static/admin/js/urlify.js HTTP/1.1" 200 7887
[05/Mar/2024 01:54:20] "GET /static/admin/js/prepopulate.js HTTP/1.1" 200 1531
[05/Mar/2024 01:54:20] "GET /static/admin/js/vendor/jquery/jquery.js HTTP/1.1" 200 285314
[05/Mar/2024 01:54:20] "GET /static/admin/js/vendor/xregexp/xregexp.js HTTP/1.1" 200 325171
[05/Mar/2024 01:54:20] "GET /static/admin/js/filters.js HTTP/1.1" 200 978
[05/Mar/2024 01:54:20] "GET /static/admin/img/tooltag-add.svg HTTP/1.1" 200 331
[05/Mar/2024 02:01:17] "GET /admin/database/links/ HTTP/1.1" 200 7432
[05/Mar/2024 02:01:17] "GET /admin/jsi18n/ HTTP/1.1" 200 3342
[05/Mar/2024 02:02:17] "GET /admin/database/links/ HTTP/1.1" 200 7432
[05/Mar/2024 02:02:17] "GET /admin/jsi18n/ HTTP/1.1" 200 3342
[05/Mar/2024 02:05:39] "GET /admin/database/links/ HTTP/1.1" 200 7432
[05/Mar/2024 02:05:39] "GET /admin/jsi18n/ HTTP/1.1" 200 3342
[05/Mar/2024 02:06:08] "OPTIONS /frontendAPI/ HTTP/1.1" 200 170
[05/Mar/2024 02:06:09] "GET /admin/database/links/ HTTP/1.1" 200 7432
[05/Mar/2024 02:06:09] "GET /admin/jsi18n/ HTTP/1.1" 200 3342
[05/Mar/2024 02:06:12] "GET /admin/database/links/ HTTP/1.1" 200 7432
[05/Mar/2024 02:06:12] "GET /admin/jsi18n/ HTTP/1.1" 200 3342
[05/Mar/2024 02:06:13] "GET /admin/database/links/ HTTP/1.1" 200 7432
[05/Mar/2024 02:06:14] "GET /admin/jsi18n/ HTTP/1.1" 200 3342
[05/Mar/2024 02:06:15] "GET /admin/database/links/ HTTP/1.1" 200 7432
[05/Mar/2024 02:06:15] "GET /admin/jsi18n/ HTTP/1.1" 200 3342
[05/Mar/2024 02:06:16] "GET /admin/database/links/ HTTP/1.1" 200 7432
[05/Mar/2024 02:06:16] "GET /admin/jsi18n/ HTTP/1.1" 200 3342
[05/Mar/2024 02:06:17] "GET /admin/database/links/ HTTP/1.1" 200 7432
[05/Mar/2024 02:06:17] "GET /admin/jsi18n/ HTTP/1.1" 200 3342
[05/Mar/2024 02:06:18] "GET /admin/database/links/ HTTP/1.1" 200 7432
[05/Mar/2024 02:06:18] "GET /admin/jsi18n/ HTTP/1.1" 200 3342
[05/Mar/2024 02:06:20] "GET /admin/database/links/ HTTP/1.1" 200 7432
[05/Mar/2024 02:06:20] "GET /admin/jsi18n/ HTTP/1.1" 200 3342
[05/Mar/2024 02:06:21] "GET /admin/database/links/ HTTP/1.1" 200 7432
[05/Mar/2024 02:06:21] "GET /admin/jsi18n/ HTTP/1.1" 200 3342
[05/Mar/2024 02:06:22] "GET /admin/database/links/ HTTP/1.1" 200 7432
[05/Mar/2024 02:06:22] "GET /admin/jsi18n/ HTTP/1.1" 200 3342
[05/Mar/2024 02:06:23] "GET /admin/database/links/ HTTP/1.1" 200 7432
[05/Mar/2024 02:06:23] "GET /admin/jsi18n/ HTTP/1.1" 200 3342
[05/Mar/2024 02:06:26] "GET /admin/database/links/ HTTP/1.1" 200 7432
[05/Mar/2024 02:06:26] "GET /admin/jsi18n/ HTTP/1.1" 200 3342
[05/Mar/2024 02:07:17] "GET /admin/database/links/ HTTP/1.1" 200 7432
[05/Mar/2024 02:07:17] "GET /admin/jsi18n/ HTTP/1.1" 200 3342
[05/Mar/2024 02:07:28] code 400, message Bad request version ('7Ë]Ä>hÅ!#\x82¯\x0f\x83Aÿÿ\x8d\x95\x06Êtï#=Õ2\x00\x90\x08IÍ\\\x91¦õ')
[05/Mar/2024 02:07:28] You're accessing the development server over HTTPS, but it only supports HTTP.
[05/Mar/2024 02:07:28] code 400, message Bad request version ('Õ¯ð\x91\x96`ä\x98W\x9b\x03ëYr³çð')
[05/Mar/2024 02:07:28] You're accessing the development server over HTTPS, but it only supports HTTP.
[05/Mar/2024 02:07:58] "GET /admin/database/links/ HTTP/1.1" 200 7432
[05/Mar/2024 02:07:58] "GET /admin/jsi18n/ HTTP/1.1" 200 3342
[05/Mar/2024 02:08:54] "OPTIONS /frontendAPI/ HTTP/1.1" 200 170
Unsupported Media Type: /frontendAPI/
[05/Mar/2024 02:08:59] "POST /frontendAPI/ HTTP/1.1" 415 76
[05/Mar/2024 02:09:05] "GET /admin/database/links/ HTTP/1.1" 200 7432
[05/Mar/2024 02:09:05] "GET /admin/jsi18n/ HTTP/1.1" 200 3342
[05/Mar/2024 02:09:07] "GET /admin/database/links/ HTTP/1.1" 200 7432
[05/Mar/2024 02:09:07] "GET /admin/jsi18n/ HTTP/1.1" 200 3342
Internal Server Error: /frontendAPI/
Traceback (most recent call last):
  File "/home/ubuntu/.local/lib/python3.10/site-packages/django/core/handlers/exception.py", line 55, in inner
    response = get_response(request)
  File "/home/ubuntu/.local/lib/python3.10/site-packages/django/core/handlers/base.py", line 197, in _get_response
    response = wrapped_callback(request, *callback_args, **callback_kwargs)
  File "/home/ubuntu/.local/lib/python3.10/site-packages/django/views/decorators/csrf.py", line 65, in _view_wrapper
    return view_func(request, *args, **kwargs)
  File "/home/ubuntu/.local/lib/python3.10/site-packages/django/views/generic/base.py", line 104, in view
    return self.dispatch(request, *args, **kwargs)
  File "/home/ubuntu/.local/lib/python3.10/site-packages/rest_framework/views.py", line 509, in dispatch
    response = self.handle_exception(exc)
  File "/home/ubuntu/.local/lib/python3.10/site-packages/rest_framework/views.py", line 469, in handle_exception
    self.raise_uncaught_exception(exc)
  File "/home/ubuntu/.local/lib/python3.10/site-packages/rest_framework/views.py", line 480, in raise_uncaught_exception
    raise exc
  File "/home/ubuntu/.local/lib/python3.10/site-packages/rest_framework/views.py", line 506, in dispatch
    response = handler(request, *args, **kwargs)
  File "/home/ubuntu/djangobackend/database/views.py", line 47, in get
    serializer = Links(network, many=True)
  File "/home/ubuntu/.local/lib/python3.10/site-packages/django/db/models/base.py", line 567, in __init__
    raise TypeError(
TypeError: Links() got unexpected keyword arguments: 'many'
[05/Mar/2024 02:10:22] "GET /frontendAPI/ HTTP/1.1" 500 93082
Unsupported Media Type: /frontendAPI/
[05/Mar/2024 02:10:22] "POST /frontendAPI/ HTTP/1.1" 415 76
Not Found: /favicon.ico
[05/Mar/2024 02:10:22] "GET /favicon.ico HTTP/1.1" 404 2764
Unsupported Media Type: /frontendAPI/
[05/Mar/2024 02:11:44] "POST /frontendAPI/ HTTP/1.1" 415 76
[05/Mar/2024 02:12:16] "GET /admin/database/links/ HTTP/1.1" 200 7432
[05/Mar/2024 02:12:16] "GET /admin/jsi18n/ HTTP/1.1" 200 3342
[05/Mar/2024 02:12:18] "GET /admin/database/ HTTP/1.1" 200 5054
[05/Mar/2024 02:12:21] "GET /admin/ HTTP/1.1" 200 6191
Unsupported Media Type: /frontendAPI/
[05/Mar/2024 02:13:46] "POST /frontendAPI/ HTTP/1.1" 415 76
Internal Server Error: /frontendAPI/
Traceback (most recent call last):
  File "/home/ubuntu/.local/lib/python3.10/site-packages/django/core/handlers/exception.py", line 55, in inner
    response = get_response(request)
  File "/home/ubuntu/.local/lib/python3.10/site-packages/django/core/handlers/base.py", line 197, in _get_response
    response = wrapped_callback(request, *callback_args, **callback_kwargs)
  File "/home/ubuntu/.local/lib/python3.10/site-packages/django/views/decorators/csrf.py", line 65, in _view_wrapper
    return view_func(request, *args, **kwargs)
  File "/home/ubuntu/.local/lib/python3.10/site-packages/django/views/generic/base.py", line 104, in view
    return self.dispatch(request, *args, **kwargs)
  File "/home/ubuntu/.local/lib/python3.10/site-packages/rest_framework/views.py", line 509, in dispatch
    response = self.handle_exception(exc)
  File "/home/ubuntu/.local/lib/python3.10/site-packages/rest_framework/views.py", line 469, in handle_exception
    self.raise_uncaught_exception(exc)
  File "/home/ubuntu/.local/lib/python3.10/site-packages/rest_framework/views.py", line 480, in raise_uncaught_exception
    raise exc
  File "/home/ubuntu/.local/lib/python3.10/site-packages/rest_framework/views.py", line 506, in dispatch
    response = handler(request, *args, **kwargs)
  File "/home/ubuntu/djangobackend/database/views.py", line 47, in get
    serializer = Links(network, many=True)
  File "/home/ubuntu/.local/lib/python3.10/site-packages/django/db/models/base.py", line 567, in __init__
    raise TypeError(
TypeError: Links() got unexpected keyword arguments: 'many'
[05/Mar/2024 02:17:39] "GET /frontendAPI/ HTTP/1.1" 500 93965
[05/Mar/2024 02:18:21] "GET / HTTP/1.1" 200 5120
[05/Mar/2024 02:18:21] "GET /static/rest_framework/css/bootstrap.min.css HTTP/1.1" 200 121457
[05/Mar/2024 02:18:21] "GET /static/rest_framework/css/bootstrap-tweaks.css HTTP/1.1" 200 3385
[05/Mar/2024 02:18:21] "GET /static/rest_framework/css/default.css HTTP/1.1" 200 1152
[05/Mar/2024 02:18:21] "GET /static/rest_framework/css/prettify.css HTTP/1.1" 200 817
[05/Mar/2024 02:18:21] "GET /static/rest_framework/js/ajax-form.js HTTP/1.1" 200 3597
[05/Mar/2024 02:18:21] "GET /static/rest_framework/js/csrf.js HTTP/1.1" 200 1719
[05/Mar/2024 02:18:21] "GET /static/rest_framework/js/bootstrap.min.js HTTP/1.1" 200 39680
[05/Mar/2024 02:18:21] "GET /static/rest_framework/js/prettify-min.js HTTP/1.1" 200 13632
[05/Mar/2024 02:18:21] "GET /static/rest_framework/js/jquery-3.5.1.min.js HTTP/1.1" 200 89476
[05/Mar/2024 02:18:21] "GET /static/rest_framework/js/default.js HTTP/1.1" 200 1268
[05/Mar/2024 02:18:21] "GET /static/rest_framework/img/grid.png HTTP/1.1" 200 1458
[05/Mar/2024 02:18:25] "GET /admin/ HTTP/1.1" 200 6191
[05/Mar/2024 02:18:27] "GET /admin/database/links/ HTTP/1.1" 200 7432
[05/Mar/2024 02:18:27] "GET /admin/jsi18n/ HTTP/1.1" 200 3342
[05/Mar/2024 02:18:33] "GET /admin/ HTTP/1.1" 200 6191
[05/Mar/2024 02:20:37] "GET /post HTTP/1.1" 301 0
Method Not Allowed: /post/
[05/Mar/2024 02:20:37] "GET /post/ HTTP/1.1" 405 5701
[05/Mar/2024 02:21:14] "GET / HTTP/1.1" 200 5120
Unsupported Media Type: /frontendAPI/
[05/Mar/2024 02:23:52] "POST /frontendAPI/ HTTP/1.1" 415 76
Unsupported Media Type: /frontendAPI/
[05/Mar/2024 02:24:52] "POST /frontendAPI/ HTTP/1.1" 415 76
[05/Mar/2024 02:26:32] code 400, message Bad request syntax ('\x16\x03\x01\x025\x01\x00\x021\x03\x03e\x1b|i5¼ÜSív\x81/Ò7èX!ãïÆo\x19?¸ÞßÔ')
[05/Mar/2024 02:26:32] You're accessing the development server over HTTPS, but it only supports HTTP.
[05/Mar/2024 02:26:32] code 400, message Bad request version ('Õ\x8a\x96É\x1aÕ¢L\x9b®\x9d\x04ÒünX\x1aQ\x00°`h\x8b#[h\x11jF\x90\x16ÿì®(\x9d\x10Rk\x01U»[£\x93\xadEöù²¼±C]')
[05/Mar/2024 02:26:32] You're accessing the development server over HTTPS, but it only supports HTTP.
Internal Server Error: /frontendAPI/
Traceback (most recent call last):
  File "/home/ubuntu/.local/lib/python3.10/site-packages/django/core/handlers/exception.py", line 55, in inner
    response = get_response(request)
  File "/home/ubuntu/.local/lib/python3.10/site-packages/django/core/handlers/base.py", line 197, in _get_response
    response = wrapped_callback(request, *callback_args, **callback_kwargs)
  File "/home/ubuntu/.local/lib/python3.10/site-packages/django/views/decorators/csrf.py", line 65, in _view_wrapper
    return view_func(request, *args, **kwargs)
  File "/home/ubuntu/.local/lib/python3.10/site-packages/django/views/generic/base.py", line 104, in view
    return self.dispatch(request, *args, **kwargs)
  File "/home/ubuntu/.local/lib/python3.10/site-packages/rest_framework/views.py", line 509, in dispatch
    response = self.handle_exception(exc)
  File "/home/ubuntu/.local/lib/python3.10/site-packages/rest_framework/views.py", line 469, in handle_exception
    self.raise_uncaught_exception(exc)
  File "/home/ubuntu/.local/lib/python3.10/site-packages/rest_framework/views.py", line 480, in raise_uncaught_exception
    raise exc
  File "/home/ubuntu/.local/lib/python3.10/site-packages/rest_framework/views.py", line 506, in dispatch
    response = handler(request, *args, **kwargs)
  File "/home/ubuntu/djangobackend/database/views.py", line 51, in post
    serializer = Links(data=request.data)
  File "/home/ubuntu/.local/lib/python3.10/site-packages/django/db/models/base.py", line 567, in __init__
    raise TypeError(
TypeError: Links() got unexpected keyword arguments: 'data'
[05/Mar/2024 02:29:53] "POST /frontendAPI/ HTTP/1.1" 500 92163
/home/ubuntu/djangobackend/database/views.py changed, reloading.
Performing system checks...

System check identified no issues (0 silenced).
March 05, 2024 - 01:54:10
Django version 5.0.1, using settings 'djangobackend.settings'
Starting development server at http://0.0.0.0:8000/
Quit the server with CONTROL-C.

Watching for file changes with StatReloader
[05/Mar/2024 02:30:21] "GET / HTTP/1.1" 200 5120
Bad Request: /frontendAPI/
[05/Mar/2024 02:30:42] "POST /frontendAPI/ HTTP/1.1" 400 28
Internal Server Error: /frontendAPI/
[05/Mar/2024 02:30:54] "POST /frontendAPI/ HTTP/1.1" 500 29
Bad Request: /frontendAPI/
[05/Mar/2024 02:30:58] "POST /frontendAPI/ HTTP/1.1" 400 28
Bad Request: /frontendAPI/
[05/Mar/2024 02:31:51] "POST /frontendAPI/ HTTP/1.1" 400 28
Internal Server Error: /frontendAPI/
[05/Mar/2024 02:34:05] "POST /frontendAPI/ HTTP/1.1" 500 29
Bad Request: /frontendAPI/
[05/Mar/2024 02:34:07] "POST /frontendAPI/ HTTP/1.1" 400 28
Bad Request: /frontendAPI/
[05/Mar/2024 02:34:07] "POST /frontendAPI/ HTTP/1.1" 400 28
Bad Request: /frontendAPI/
[05/Mar/2024 02:34:07] "POST /frontendAPI/ HTTP/1.1" 400 28
Bad Request: /frontendAPI/
[05/Mar/2024 02:34:08] "POST /frontendAPI/ HTTP/1.1" 400 28
Bad Request: /frontendAPI/
[05/Mar/2024 02:34:08] "POST /frontendAPI/ HTTP/1.1" 400 28
Bad Request: /frontendAPI/
[05/Mar/2024 02:34:08] "POST /frontendAPI/ HTTP/1.1" 400 28
Bad Request: /frontendAPI/
[05/Mar/2024 02:34:08] "POST /frontendAPI/ HTTP/1.1" 400 28
Bad Request: /frontendAPI/
[05/Mar/2024 02:34:08] "POST /frontendAPI/ HTTP/1.1" 400 28
Bad Request: /frontendAPI/
[05/Mar/2024 02:34:08] "POST /frontendAPI/ HTTP/1.1" 400 28
Bad Request: /frontendAPI/
[05/Mar/2024 02:34:08] "POST /frontendAPI/ HTTP/1.1" 400 28
Bad Request: /frontendAPI/
[05/Mar/2024 02:34:09] "POST /frontendAPI/ HTTP/1.1" 400 28
Bad Request: /frontendAPI/
[05/Mar/2024 02:34:19] "POST /frontendAPI/ HTTP/1.1" 400 28
Bad Request: /frontendAPI/
[05/Mar/2024 02:34:20] "POST /frontendAPI/ HTTP/1.1" 400 28
Bad Request: /frontendAPI/
[05/Mar/2024 02:34:20] "POST /frontendAPI/ HTTP/1.1" 400 28
Bad Request: /frontendAPI/
[05/Mar/2024 02:34:20] "POST /frontendAPI/ HTTP/1.1" 400 28
Bad Request: /frontendAPI/
[05/Mar/2024 02:34:20] "POST /frontendAPI/ HTTP/1.1" 400 28
Bad Request: /frontendAPI/
[05/Mar/2024 02:34:20] "POST /frontendAPI/ HTTP/1.1" 400 28
Bad Request: /frontendAPI/
[05/Mar/2024 02:34:20] "POST /frontendAPI/ HTTP/1.1" 400 28
Bad Request: /frontendAPI/
[05/Mar/2024 02:34:42] "POST /frontendAPI/ HTTP/1.1" 400 28
[05/Mar/2024 02:34:54] "GET /website HTTP/1.1" 301 0
[05/Mar/2024 02:34:54] "GET /website/ HTTP/1.1" 200 669
Internal Server Error: /frontendAPI/
[05/Mar/2024 02:38:22] "POST /frontendAPI/ HTTP/1.1" 500 29
Internal Server Error: /frontendAPI/
[05/Mar/2024 02:43:20] "POST /frontendAPI/ HTTP/1.1" 500 29
Internal Server Error: /frontendAPI/
[05/Mar/2024 02:43:22] "POST /frontendAPI/ HTTP/1.1" 500 29
/home/ubuntu/djangobackend/database/views.py changed, reloading.
Performing system checks...

System check identified no issues (0 silenced).
March 05, 2024 - 02:30:10
Django version 5.0.1, using settings 'djangobackend.settings'
Starting development server at http://0.0.0.0:8000/
Quit the server with CONTROL-C.

Validation Error: {'domainURL': [ErrorDetail(string='This field is required.', code='required')], 'domainTitle': [ErrorDetail(string='This field is required.', code='required')], 'timeAccessed': [ErrorDetail(string='This field is required.', code='required')]}
Error: Unsupported media type "text/plain;charset=UTF-8" in request.
Validation Error: {'domainURL': [ErrorDetail(string='This field is required.', code='required')], 'domainTitle': [ErrorDetail(string='This field is required.', code='required')], 'timeAccessed': [ErrorDetail(string='This field is required.', code='required')]}
Validation Error: {'domainURL': [ErrorDetail(string='This field is required.', code='required')], 'domainTitle': [ErrorDetail(string='This field is required.', code='required')], 'timeAccessed': [ErrorDetail(string='This field is required.', code='required')]}
Error: Unsupported media type "text/plain;charset=UTF-8" in request.
Validation Error: {'domainURL': [ErrorDetail(string='This field is required.', code='required')], 'domainTitle': [ErrorDetail(string='This field is required.', code='required')], 'timeAccessed': [ErrorDetail(string='This field is required.', code='required')]}
Validation Error: {'domainURL': [ErrorDetail(string='This field is required.', code='required')], 'domainTitle': [ErrorDetail(string='This field is required.', code='required')], 'timeAccessed': [ErrorDetail(string='This field is required.', code='required')]}
Validation Error: {'domainURL': [ErrorDetail(string='This field is required.', code='required')], 'domainTitle': [ErrorDetail(string='This field is required.', code='required')], 'timeAccessed': [ErrorDetail(string='This field is required.', code='required')]}
Validation Error: {'domainURL': [ErrorDetail(string='This field is required.', code='required')], 'domainTitle': [ErrorDetail(string='This field is required.', code='required')], 'timeAccessed': [ErrorDetail(string='This field is required.', code='required')]}
Validation Error: {'domainURL': [ErrorDetail(string='This field is required.', code='required')], 'domainTitle': [ErrorDetail(string='This field is required.', code='required')], 'timeAccessed': [ErrorDetail(string='This field is required.', code='required')]}
Validation Error: {'domainURL': [ErrorDetail(string='This field is required.', code='required')], 'domainTitle': [ErrorDetail(string='This field is required.', code='required')], 'timeAccessed': [ErrorDetail(string='This field is required.', code='required')]}
Validation Error: {'domainURL': [ErrorDetail(string='This field is required.', code='required')], 'domainTitle': [ErrorDetail(string='This field is required.', code='required')], 'timeAccessed': [ErrorDetail(string='This field is required.', code='required')]}
Validation Error: {'domainURL': [ErrorDetail(string='This field is required.', code='required')], 'domainTitle': [ErrorDetail(string='This field is required.', code='required')], 'timeAccessed': [ErrorDetail(string='This field is required.', code='required')]}
Validation Error: {'domainURL': [ErrorDetail(string='This field is required.', code='required')], 'domainTitle': [ErrorDetail(string='This field is required.', code='required')], 'timeAccessed': [ErrorDetail(string='This field is required.', code='required')]}
Validation Error: {'domainURL': [ErrorDetail(string='This field is required.', code='required')], 'domainTitle': [ErrorDetail(string='This field is required.', code='required')], 'timeAccessed': [ErrorDetail(string='This field is required.', code='required')]}
Validation Error: {'domainURL': [ErrorDetail(string='This field is required.', code='required')], 'domainTitle': [ErrorDetail(string='This field is required.', code='required')], 'timeAccessed': [ErrorDetail(string='This field is required.', code='required')]}
Validation Error: {'domainURL': [ErrorDetail(string='This field is required.', code='required')], 'domainTitle': [ErrorDetail(string='This field is required.', code='required')], 'timeAccessed': [ErrorDetail(string='This field is required.', code='required')]}
Validation Error: {'domainURL': [ErrorDetail(string='This field is required.', code='required')], 'domainTitle': [ErrorDetail(string='This field is required.', code='required')], 'timeAccessed': [ErrorDetail(string='This field is required.', code='required')]}
Validation Error: {'domainURL': [ErrorDetail(string='This field is required.', code='required')], 'domainTitle': [ErrorDetail(string='This field is required.', code='required')], 'timeAccessed': [ErrorDetail(string='This field is required.', code='required')]}
Validation Error: {'domainURL': [ErrorDetail(string='This field is required.', code='required')], 'domainTitle': [ErrorDetail(string='This field is required.', code='required')], 'timeAccessed': [ErrorDetail(string='This field is required.', code='required')]}
Validation Error: {'domainURL': [ErrorDetail(string='This field is required.', code='required')], 'domainTitle': [ErrorDetail(string='This field is required.', code='required')], 'timeAccessed': [ErrorDetail(string='This field is required.', code='required')]}
Validation Error: {'domainURL': [ErrorDetail(string='This field is required.', code='required')], 'domainTitle': [ErrorDetail(string='This field is required.', code='required')], 'timeAccessed': [ErrorDetail(string='This field is required.', code='required')]}
Validation Error: {'domainURL': [ErrorDetail(string='This field is required.', code='required')], 'domainTitle': [ErrorDetail(string='This field is required.', code='required')], 'timeAccessed': [ErrorDetail(string='This field is required.', code='required')]}
Validation Error: {'domainURL': [ErrorDetail(string='This field is required.', code='required')], 'domainTitle': [ErrorDetail(string='This field is required.', code='required')], 'timeAccessed': [ErrorDetail(string='This field is required.', code='required')]}
Error: Unsupported media type "text/plain;charset=UTF-8" in request.
Error: Unsupported media type "text/plain;charset=UTF-8" in request.
Error: Unsupported media type "text/plain;charset=UTF-8" in request.
Watching for file changes with StatReloader
Internal Server Error: /frontendAPI/
[05/Mar/2024 02:44:21] "POST /frontendAPI/ HTTP/1.1" 500 29
Internal Server Error: /frontendAPI/
[05/Mar/2024 02:44:23] "POST /frontendAPI/ HTTP/1.1" 500 29
Internal Server Error: /frontendAPI/
[05/Mar/2024 02:44:24] "POST /frontendAPI/ HTTP/1.1" 500 29
Internal Server Error: /frontendAPI/
[05/Mar/2024 02:45:08] "POST /frontendAPI/ HTTP/1.1" 500 29
/home/ubuntu/djangobackend/database/views.py changed, reloading.
Performing system checks...

System check identified no issues (0 silenced).
March 05, 2024 - 02:44:13
Django version 5.0.1, using settings 'djangobackend.settings'
Starting development server at http://0.0.0.0:8000/
Quit the server with CONTROL-C.

Error: Unsupported media type "text/plain;charset=UTF-8" in request.
Error: Unsupported media type "text/plain;charset=UTF-8" in request.
Error: Unsupported media type "text/plain;charset=UTF-8" in request.
Error: Unsupported media type "text/plain;charset=UTF-8" in request.
Watching for file changes with StatReloader
Unsupported Media Type: /frontendAPI/
[05/Mar/2024 02:47:25] "POST /frontendAPI/ HTTP/1.1" 415 76
/home/ubuntu/djangobackend/database/views.py changed, reloading.
Performing system checks...

System check identified no issues (0 silenced).
March 05, 2024 - 02:47:22
Django version 5.0.1, using settings 'djangobackend.settings'
Starting development server at http://0.0.0.0:8000/
Quit the server with CONTROL-C.

Watching for file changes with StatReloader
Internal Server Error: /frontendAPI/
Traceback (most recent call last):
  File "/home/ubuntu/.local/lib/python3.10/site-packages/django/core/handlers/exception.py", line 55, in inner
    response = get_response(request)
  File "/home/ubuntu/.local/lib/python3.10/site-packages/django/core/handlers/base.py", line 197, in _get_response
    response = wrapped_callback(request, *callback_args, **callback_kwargs)
  File "/home/ubuntu/.local/lib/python3.10/site-packages/django/views/decorators/csrf.py", line 65, in _view_wrapper
    return view_func(request, *args, **kwargs)
  File "/home/ubuntu/.local/lib/python3.10/site-packages/django/views/generic/base.py", line 104, in view
    return self.dispatch(request, *args, **kwargs)
  File "/home/ubuntu/.local/lib/python3.10/site-packages/rest_framework/views.py", line 509, in dispatch
    response = self.handle_exception(exc)
  File "/home/ubuntu/.local/lib/python3.10/site-packages/rest_framework/views.py", line 469, in handle_exception
    self.raise_uncaught_exception(exc)
  File "/home/ubuntu/.local/lib/python3.10/site-packages/rest_framework/views.py", line 480, in raise_uncaught_exception
    raise exc
  File "/home/ubuntu/.local/lib/python3.10/site-packages/rest_framework/views.py", line 506, in dispatch
    response = handler(request, *args, **kwargs)
  File "/home/ubuntu/djangobackend/database/views.py", line 57, in post
    parsed = json.loads(request)
  File "/usr/lib/python3.10/json/__init__.py", line 339, in loads
    raise TypeError(f'the JSON object must be str, bytes or bytearray, '
TypeError: the JSON object must be str, bytes or bytearray, not Request
[05/Mar/2024 02:53:54] code 400, message Bad request version ('Time)","domainRating":3,"reasonNoHttps":true,"reasonShortened":false,"reasonAtSymbol":false,"reasonBadExtension":false,"clicked_count":0}')
[05/Mar/2024 02:53:54] "{"domainURL":"http://www.unsafewebsite.com/","domainTitle":"Unsafe Website from plug n' play hub","eventTime":"Mon Mar 04 2024 20:53:53 GMT-0600 (Central Standard Time)","domainRating":3,"reasonNoHttps":true,"reasonShortened":false,"reasonAtSymbol":false,"reasonBadExtension":false,"clicked_count":0}" 400 -
[05/Mar/2024 02:53:54,258] - Broken pipe from ('104.194.106.81', 51931)
/home/ubuntu/djangobackend/database/views.py changed, reloading.
Performing system checks...

System check identified no issues (0 silenced).
March 05, 2024 - 02:53:49
Django version 5.0.1, using settings 'djangobackend.settings'
Starting development server at http://0.0.0.0:8000/
Quit the server with CONTROL-C.

Watching for file changes with StatReloader
Unsupported Media Type: /frontendAPI/
[05/Mar/2024 02:57:03] "POST /frontendAPI/ HTTP/1.1" 415 76
/home/ubuntu/djangobackend/database/views.py changed, reloading.
Performing system checks...

System check identified no issues (0 silenced).
March 05, 2024 - 02:56:57
Django version 5.0.1, using settings 'djangobackend.settings'
Starting development server at http://0.0.0.0:8000/
Quit the server with CONTROL-C.

{'domainURL': 'http://www.unsafewebsite.com/', 'domainTitle': "Unsafe Website from plug n' play hub", 'eventTime': 'Mon Mar 04 2024 20:57:03 GMT-0600 (Central Standard Time)', 'domainRating': 3, 'reasonNoHttps': True, 'reasonShortened': False, 'reasonAtSymbol': False, 'reasonBadExtension': False, 'clicked_count': 0}
Watching for file changes with StatReloader
/home/ubuntu/djangobackend/database/models.py changed, reloading.
Performing system checks...

System check identified no issues (0 silenced).
March 05, 2024 - 02:58:51
Django version 5.0.1, using settings 'djangobackend.settings'
Starting development server at http://0.0.0.0:8000/
Quit the server with CONTROL-C.

Watching for file changes with StatReloader
Unsupported Media Type: /frontendAPI/
[05/Mar/2024 03:00:57] "POST /frontendAPI/ HTTP/1.1" 415 76
Not Found: /.env
[05/Mar/2024 09:04:45] "GET /.env HTTP/1.1" 404 2707
[05/Mar/2024 10:34:45] code 400, message Bad request version ('OÑËÜ®Ëd')
[05/Mar/2024 10:34:45] "   TZ         .    I¨À )z» zÚf Ò~Uñi»©                ÃÐ¢|¦v½óOÑËÜ®Ëd" 400 -
[05/Mar/2024 11:03:07] "GET / HTTP/1.1" 200 2
[05/Mar/2024 11:34:25] "GET / HTTP/1.1" 200 2
[05/Mar/2024 14:26:35] "GET / HTTP/1.1" 200 2
[05/Mar/2024 14:44:09] code 400, message Bad request version ('À\x14À')
[05/Mar/2024 14:44:09] You're accessing the development server over HTTPS, but it only supports HTTP.
[05/Mar/2024 16:31:57,548] - Broken pipe from ('199.45.155.16', 53892)
[05/Mar/2024 16:32:00] "GET / HTTP/1.1" 200 2
[05/Mar/2024 16:32:00,967] - Broken pipe from ('199.45.155.16', 53920)
[05/Mar/2024 16:32:04] "GET / HTTP/1.1" 200 2
[05/Mar/2024 16:32:04] code 505, message Invalid HTTP version (2.0)
[05/Mar/2024 16:32:04] "PRI * HTTP/2.0" 505 -
Not Found: /favicon.ico
[05/Mar/2024 16:32:05] "GET /favicon.ico HTTP/1.1" 404 2728
[05/Mar/2024 17:33:32] code 400, message Bad request version ('À\x13À')
[05/Mar/2024 17:33:32] You're accessing the development server over HTTPS, but it only supports HTTP.
[05/Mar/2024 17:33:32] code 400, message Bad request version ('À(À$À\x14À')
[05/Mar/2024 17:33:32] You're accessing the development server over HTTPS, but it only supports HTTP.
[05/Mar/2024 18:37:51] code 400, message Bad request syntax ('SSH-2.0-OpenSSH')
[05/Mar/2024 18:37:51] "SSH-2.0-OpenSSH" 400 -
[05/Mar/2024 18:49:30] "GET / HTTP/1.1" 200 2
[05/Mar/2024 20:55:41] "GET / HTTP/1.1" 200 2
[05/Mar/2024 20:56:29] "GET / HTTP/1.1" 200 2
Not Found: /favicon.ico
[05/Mar/2024 20:56:30] "GET /favicon.ico HTTP/1.1" 404 2728
Not Found: /.env
[05/Mar/2024 21:15:35] "GET /.env HTTP/1.1" 404 2707
[06/Mar/2024 01:12:32] "GET / HTTP/1.1" 200 2
[06/Mar/2024 04:24:32] code 400, message Bad request syntax ('MGLNDD_18.223.137.231_8000')
[06/Mar/2024 04:24:32] "MGLNDD_18.223.137.231_8000" 400 -
[06/Mar/2024 05:01:17] "GET / HTTP/1.1" 200 2
[06/Mar/2024 09:21:52] "GET / HTTP/1.1" 200 2
[06/Mar/2024 09:21:53] code 400, message Bad request syntax ('\x16\x03\x01\x00î\x01\x00\x00ê\x03\x03\x7f\x12>-,\x96å')
[06/Mar/2024 09:21:53] You're accessing the development server over HTTPS, but it only supports HTTP.
[06/Mar/2024 09:21:53] code 400, message Bad HTTP/0.9 request type ('t3')
[06/Mar/2024 09:21:53] "t3 12.1.2" 400 -
[06/Mar/2024 09:22:01] "GET / HTTP/1.1" 200 5085
Not Found: /favicon.ico
[06/Mar/2024 09:22:01] "GET /favicon.ico HTTP/1.1" 404 2728
[06/Mar/2024 09:22:02] "GET /static/rest_framework/js/default.js HTTP/1.1" 200 1268
[06/Mar/2024 09:22:03] "GET /static/rest_framework/js/csrf.js HTTP/1.1" 200 1719
[06/Mar/2024 09:22:03] "GET /static/rest_framework/js/ajax-form.js HTTP/1.1" 200 3597
Not Found: /robots.txt
[06/Mar/2024 09:22:04] "GET /robots.txt HTTP/1.1" 404 2725
Not Found: /sitemap.xml
[06/Mar/2024 09:22:04] "GET /sitemap.xml HTTP/1.1" 404 2728
Not Found: /.env
[06/Mar/2024 18:24:43] "GET /.env HTTP/1.1" 404 2707
[06/Mar/2024 19:41:17] "GET / HTTP/1.1" 200 2
[06/Mar/2024 22:34:24] code 400, message Bad HTTP/0.9 request type ('\x16\x03\x01\x00{\x01\x00\x00w\x03\x03V«¬\x03\x8e\x86êÐÚÔÂð_\x997ñ\x89=ÉÁ^æ\\ÓsÄï-[ëáx\x00\x00\x1aÀ/À+À\x11À\x07À\x13À')
[06/Mar/2024 22:34:24] You're accessing the development server over HTTPS, but it only supports HTTP.
Not Found: /.env
[07/Mar/2024 04:28:33] "GET /.env HTTP/1.1" 404 2707
[07/Mar/2024 05:17:18] code 400, message Bad request version ('À\x13À')
[07/Mar/2024 05:17:18] You're accessing the development server over HTTPS, but it only supports HTTP.
[07/Mar/2024 05:17:18] code 400, message Bad request version ('À(À$À\x14À')
[07/Mar/2024 05:17:18] You're accessing the development server over HTTPS, but it only supports HTTP.
[07/Mar/2024 06:38:33] "GET / HTTP/1.1" 200 2
[07/Mar/2024 07:18:37] "GET / HTTP/1.1" 200 2
[07/Mar/2024 07:31:12] "GET / HTTP/1.1" 200 2
[07/Mar/2024 12:22:01] code 400, message Bad request version ('À\x14À')
[07/Mar/2024 12:22:01] You're accessing the development server over HTTPS, but it only supports HTTP.
[07/Mar/2024 18:37:14] "GET / HTTP/1.1" 200 2
[07/Mar/2024 20:28:11] code 400, message Bad request version ('À\x13À')
[07/Mar/2024 20:28:11] You're accessing the development server over HTTPS, but it only supports HTTP.
[07/Mar/2024 20:28:11] code 400, message Bad HTTP/0.9 request type ("\x16\x03\x01\x00Ê\x01\x00\x00Æ\x03\x03\x90±ò!\x16ñÖce&íðvû$Gá49ã'kð\x9eg\x99Ù«2Sïa\x00\x00hÌ\x14Ì\x13À/À+À0À,À\x11À\x07À'À#À\x13À")
[07/Mar/2024 20:28:11] You're accessing the development server over HTTPS, but it only supports HTTP.
[08/Mar/2024 00:14:26] "GET / HTTP/1.1" 200 2
[08/Mar/2024 00:49:12] code 400, message Bad request version ('cof\x91À\x80sJ5Ò\x80æ\x9a~¹Ç\x83^\x96îN\x16\x96\x96&æ\x03ê¼\x81\x02=¬\x10ú?7\x03Ãß÷ä\x98`pæ\x8dÁ©\x8dÆ\x06Û¯\x91ç\x82s÷\x14HÔáW\x9a\x93C\x9e]¤\x01#\x03#\x03]\x03c]CC\x05C\x03+S\x03bô\x00\x00/\x9e\x16E')
[08/Mar/2024 00:49:12] "    ¿      NIMABIJIAN  {CaigÇeBÅ	Áa	cofÀsJ5Òæ~¹Ç^îN&æê¼=¬ú?7Ãß÷ä`pæÁ©ÆÛ¯çs÷HÔáWC]¤##]c]CCC+Sbô  /E" 400 -
Not Found: /.env
[08/Mar/2024 00:56:26] "GET /.env HTTP/1.1" 404 2707
[08/Mar/2024 02:23:55] "GET / HTTP/1.1" 200 2
[08/Mar/2024 02:58:13] "GET / HTTP/1.1" 200 2
Not Found: /favicon.ico
[08/Mar/2024 02:58:29] "GET /favicon.ico HTTP/1.1" 404 2728
Invalid HTTP_HOST header: 'api.ipify.org'. You may need to add 'api.ipify.org' to ALLOWED_HOSTS.
Traceback (most recent call last):
  File "/home/ubuntu/.local/lib/python3.10/site-packages/django/core/handlers/exception.py", line 55, in inner
    response = get_response(request)
  File "/home/ubuntu/.local/lib/python3.10/site-packages/django/utils/deprecation.py", line 133, in __call__
    response = self.process_request(request)
  File "/home/ubuntu/.local/lib/python3.10/site-packages/django/middleware/common.py", line 48, in process_request
    host = request.get_host()
  File "/home/ubuntu/.local/lib/python3.10/site-packages/django/http/request.py", line 151, in get_host
    raise DisallowedHost(msg)
django.core.exceptions.DisallowedHost: Invalid HTTP_HOST header: 'api.ipify.org'. You may need to add 'api.ipify.org' to ALLOWED_HOSTS.
Bad Request: /http:/api.ipify.org/
[08/Mar/2024 02:58:33] "GET http://api.ipify.org/?format=json HTTP/1.1" 400 63784
Invalid HTTP_HOST header: 'www.shadowserver.org'. You may need to add 'www.shadowserver.org' to ALLOWED_HOSTS.
Traceback (most recent call last):
  File "/home/ubuntu/.local/lib/python3.10/site-packages/django/core/handlers/exception.py", line 55, in inner
    response = get_response(request)
  File "/home/ubuntu/.local/lib/python3.10/site-packages/django/utils/deprecation.py", line 133, in __call__
    response = self.process_request(request)
  File "/home/ubuntu/.local/lib/python3.10/site-packages/django/middleware/common.py", line 48, in process_request
    host = request.get_host()
  File "/home/ubuntu/.local/lib/python3.10/site-packages/django/http/request.py", line 151, in get_host
    raise DisallowedHost(msg)
django.core.exceptions.DisallowedHost: Invalid HTTP_HOST header: 'www.shadowserver.org'. You may need to add 'www.shadowserver.org' to ALLOWED_HOSTS.
Bad Request: /www.shadowserver.org:443
[08/Mar/2024 02:58:36] "CONNECT www.shadowserver.org:443 HTTP/1.1" 400 63987
[08/Mar/2024 07:02:52] code 400, message Bad request version ('À\x13À')
[08/Mar/2024 07:02:52] You're accessing the development server over HTTPS, but it only supports HTTP.
[08/Mar/2024 07:02:52] "GET / HTTP/1.1" 200 5085
[08/Mar/2024 07:02:53] code 400, message Bad HTTP/0.9 request type ('\x16\x03\x01\x00î\x01\x00\x00ê\x03\x03Æ-\x99\x91¼u^8rç')
[08/Mar/2024 07:02:53] You're accessing the development server over HTTPS, but it only supports HTTP.
[08/Mar/2024 07:02:53] code 400, message Bad request version ('eÁ·')
[08/Mar/2024 07:02:53] You're accessing the development server over HTTPS, but it only supports HTTP.
[08/Mar/2024 07:02:54] code 400, message Bad request version ('À\x13À')
[08/Mar/2024 07:02:54] You're accessing the development server over HTTPS, but it only supports HTTP.
[08/Mar/2024 07:02:54] code 400, message Bad request syntax ("\x16\x03\x01\x00î\x01\x00\x00ê\x03\x03\x12\x0f¤»ðQTÙ¶NÆH\x92ÐÊ'tÄçÔì")
[08/Mar/2024 07:02:54] You're accessing the development server over HTTPS, but it only supports HTTP.
[08/Mar/2024 07:02:55] code 400, message Bad request version ('À\x13À')
[08/Mar/2024 07:02:55] You're accessing the development server over HTTPS, but it only supports HTTP.
[08/Mar/2024 07:02:55] code 400, message Bad request version ('À\x13À')
[08/Mar/2024 07:02:55] You're accessing the development server over HTTPS, but it only supports HTTP.
[08/Mar/2024 09:23:15] "GET / HTTP/1.1" 200 2
[08/Mar/2024 10:52:57] code 400, message Bad request version ('À\x14À')
[08/Mar/2024 10:52:57] You're accessing the development server over HTTPS, but it only supports HTTP.
[08/Mar/2024 11:02:38] "GET / HTTP/1.1" 200 2
[08/Mar/2024 11:09:54] code 400, message Bad request version ('À\x14À')
[08/Mar/2024 11:09:54] You're accessing the development server over HTTPS, but it only supports HTTP.
[08/Mar/2024 11:43:52] "GET / HTTP/1.1" 200 5085
Not Found: /favicon.ico
[08/Mar/2024 11:43:52] "GET /favicon.ico HTTP/1.1" 404 2728
[08/Mar/2024 11:43:53] "GET /static/rest_framework/js/default.js HTTP/1.1" 200 1268
[08/Mar/2024 11:43:53] "GET /static/rest_framework/js/ajax-form.js HTTP/1.1" 200 3597
[08/Mar/2024 11:43:53] "GET /static/rest_framework/js/csrf.js HTTP/1.1" 200 1719
Not Found: /sitemap.xml
[08/Mar/2024 11:43:53] "GET /sitemap.xml HTTP/1.1" 404 2728
Not Found: /robots.txt
[08/Mar/2024 11:43:53] "GET /robots.txt HTTP/1.1" 404 2725
[08/Mar/2024 12:09:01] "GET / HTTP/1.1" 200 5085
Not Found: /.DS_Store
[08/Mar/2024 18:01:44] "GET /.DS_Store HTTP/1.1" 404 2722
[08/Mar/2024 19:15:10] "GET / HTTP/1.1" 200 2
[08/Mar/2024 21:08:32] "GET / HTTP/1.1" 200 5085
Not Found: /.vscode/sftp.json
[08/Mar/2024 21:12:06] "GET /.vscode/sftp.json HTTP/1.1" 404 2746
Invalid HTTP_HOST header: '185.65.245.140:7227'. You may need to add '185.65.245.140' to ALLOWED_HOSTS.
Traceback (most recent call last):
  File "/home/ubuntu/.local/lib/python3.10/site-packages/django/core/handlers/exception.py", line 55, in inner
    response = get_response(request)
  File "/home/ubuntu/.local/lib/python3.10/site-packages/django/utils/deprecation.py", line 133, in __call__
    response = self.process_request(request)
  File "/home/ubuntu/.local/lib/python3.10/site-packages/django/middleware/common.py", line 48, in process_request
    host = request.get_host()
  File "/home/ubuntu/.local/lib/python3.10/site-packages/django/http/request.py", line 151, in get_host
    raise DisallowedHost(msg)
django.core.exceptions.DisallowedHost: Invalid HTTP_HOST header: '185.65.245.140:7227'. You may need to add '185.65.245.140' to ALLOWED_HOSTS.
Bad Request: /185.65.245.140:7227
Invalid HTTP_HOST header: '193.149.189.126:7227'. You may need to add '193.149.189.126' to ALLOWED_HOSTS.
Traceback (most recent call last):
  File "/home/ubuntu/.local/lib/python3.10/site-packages/django/core/handlers/exception.py", line 55, in inner
    response = get_response(request)
  File "/home/ubuntu/.local/lib/python3.10/site-packages/django/utils/deprecation.py", line 133, in __call__
    response = self.process_request(request)
  File "/home/ubuntu/.local/lib/python3.10/site-packages/django/middleware/common.py", line 48, in process_request
    host = request.get_host()
  File "/home/ubuntu/.local/lib/python3.10/site-packages/django/http/request.py", line 151, in get_host
    raise DisallowedHost(msg)
django.core.exceptions.DisallowedHost: Invalid HTTP_HOST header: '193.149.189.126:7227'. You may need to add '193.149.189.126' to ALLOWED_HOSTS.
Bad Request: /193.149.189.126:7227
Invalid HTTP_HOST header: '193.149.189.126:7227'. You may need to add '193.149.189.126' to ALLOWED_HOSTS.
Traceback (most recent call last):
  File "/home/ubuntu/.local/lib/python3.10/site-packages/django/core/handlers/exception.py", line 55, in inner
    response = get_response(request)
  File "/home/ubuntu/.local/lib/python3.10/site-packages/django/utils/deprecation.py", line 133, in __call__
    response = self.process_request(request)
  File "/home/ubuntu/.local/lib/python3.10/site-packages/django/middleware/common.py", line 48, in process_request
    host = request.get_host()
  File "/home/ubuntu/.local/lib/python3.10/site-packages/django/http/request.py", line 151, in get_host
    raise DisallowedHost(msg)
django.core.exceptions.DisallowedHost: Invalid HTTP_HOST header: '193.149.189.126:7227'. You may need to add '193.149.189.126' to ALLOWED_HOSTS.
Bad Request: /193.149.189.126:7227
[08/Mar/2024 23:11:21] "GET / HTTP/1.1" 200 2
[08/Mar/2024 23:11:31] code 505, message Invalid HTTP version (2.0)
[08/Mar/2024 23:11:31] "PRI * HTTP/2.0" 505 -
Not Found: /favicon.ico
[08/Mar/2024 23:11:31] "GET /favicon.ico HTTP/1.1" 404 2728
Not Found: /.git/config
[09/Mar/2024 00:13:13] "GET /.git/config HTTP/1.1" 404 2728
[09/Mar/2024 00:34:57] code 400, message Bad HTTP/0.9 request type ('Z¥\x01')
[09/Mar/2024 00:34:57] "Z¥     " 400 -
Not Found: /favicon.ico
[09/Mar/2024 01:03:40] "GET /favicon.ico HTTP/1.1" 404 2728
Invalid HTTP_HOST header: 'ip-172-31-12-79.us-east-2.compute.internal:8000'. You may need to add 'ip-172-31-12-79.us-east-2.compute.internal' to ALLOWED_HOSTS.
Traceback (most recent call last):
  File "/home/ubuntu/.local/lib/python3.10/site-packages/django/core/handlers/exception.py", line 55, in inner
    response = get_response(request)
  File "/home/ubuntu/.local/lib/python3.10/site-packages/django/utils/deprecation.py", line 133, in __call__
    response = self.process_request(request)
  File "/home/ubuntu/.local/lib/python3.10/site-packages/django/middleware/common.py", line 48, in process_request
    host = request.get_host()
  File "/home/ubuntu/.local/lib/python3.10/site-packages/django/http/request.py", line 151, in get_host
    raise DisallowedHost(msg)
django.core.exceptions.DisallowedHost: Invalid HTTP_HOST header: 'ip-172-31-12-79.us-east-2.compute.internal:8000'. You may need to add 'ip-172-31-12-79.us-east-2.compute.internal' to ALLOWED_HOSTS.
Bad Request: /
[09/Mar/2024 03:51:09] "GET / HTTP/1.0" 400 63578
[09/Mar/2024 05:02:22] "GET / HTTP/1.1" 200 2
[09/Mar/2024 07:01:47] "GET / HTTP/1.1" 200 2
Not Found: /api/session/properties
[09/Mar/2024 10:02:48] "GET /api/session/properties HTTP/1.1" 404 2761
[09/Mar/2024 10:03:07] "GET / HTTP/1.1" 200 2
[09/Mar/2024 10:03:22] "GET / HTTP/1.1" 200 2
[09/Mar/2024 10:03:25] "GET /admin/ HTTP/1.1" 302 0
[09/Mar/2024 12:38:59] "GET / HTTP/1.1" 200 2
Not Found: /favicon.ico
[09/Mar/2024 12:39:23] "GET /favicon.ico HTTP/1.1" 404 2728
Invalid HTTP_HOST header: 'api.ipify.org'. You may need to add 'api.ipify.org' to ALLOWED_HOSTS.
Traceback (most recent call last):
  File "/home/ubuntu/.local/lib/python3.10/site-packages/django/core/handlers/exception.py", line 55, in inner
    response = get_response(request)
  File "/home/ubuntu/.local/lib/python3.10/site-packages/django/utils/deprecation.py", line 133, in __call__
    response = self.process_request(request)
  File "/home/ubuntu/.local/lib/python3.10/site-packages/django/middleware/common.py", line 48, in process_request
    host = request.get_host()
  File "/home/ubuntu/.local/lib/python3.10/site-packages/django/http/request.py", line 151, in get_host
    raise DisallowedHost(msg)
django.core.exceptions.DisallowedHost: Invalid HTTP_HOST header: 'api.ipify.org'. You may need to add 'api.ipify.org' to ALLOWED_HOSTS.
Bad Request: /http:/api.ipify.org/
[09/Mar/2024 12:39:26] "GET http://api.ipify.org/?format=json HTTP/1.1" 400 63718
Invalid HTTP_HOST header: 'www.shadowserver.org'. You may need to add 'www.shadowserver.org' to ALLOWED_HOSTS.
Traceback (most recent call last):
  File "/home/ubuntu/.local/lib/python3.10/site-packages/django/core/handlers/exception.py", line 55, in inner
    response = get_response(request)
  File "/home/ubuntu/.local/lib/python3.10/site-packages/django/utils/deprecation.py", line 133, in __call__
    response = self.process_request(request)
  File "/home/ubuntu/.local/lib/python3.10/site-packages/django/middleware/common.py", line 48, in process_request
    host = request.get_host()
  File "/home/ubuntu/.local/lib/python3.10/site-packages/django/http/request.py", line 151, in get_host
    raise DisallowedHost(msg)
django.core.exceptions.DisallowedHost: Invalid HTTP_HOST header: 'www.shadowserver.org'. You may need to add 'www.shadowserver.org' to ALLOWED_HOSTS.
Bad Request: /www.shadowserver.org:443
[09/Mar/2024 12:39:30] "CONNECT www.shadowserver.org:443 HTTP/1.1" 400 63921
Not Found: /.env
[09/Mar/2024 13:25:05] "GET /.env HTTP/1.1" 404 2707
[09/Mar/2024 14:29:59] "GET / HTTP/1.1" 200 2
[09/Mar/2024 19:47:35] code 400, message Bad request syntax ('MGLNDD_18.223.137.231_8000')
[09/Mar/2024 19:47:35] "MGLNDD_18.223.137.231_8000" 400 -
[09/Mar/2024 21:42:45] "GET / HTTP/1.1" 200 2
[09/Mar/2024 21:57:17] "GET / HTTP/1.1" 200 2
Invalid HTTP_HOST header: '45.61.136.175:7227'. You may need to add '45.61.136.175' to ALLOWED_HOSTS.
Traceback (most recent call last):
  File "/home/ubuntu/.local/lib/python3.10/site-packages/django/core/handlers/exception.py", line 55, in inner
    response = get_response(request)
  File "/home/ubuntu/.local/lib/python3.10/site-packages/django/utils/deprecation.py", line 133, in __call__
    response = self.process_request(request)
  File "/home/ubuntu/.local/lib/python3.10/site-packages/django/middleware/common.py", line 48, in process_request
    host = request.get_host()
  File "/home/ubuntu/.local/lib/python3.10/site-packages/django/http/request.py", line 151, in get_host
    raise DisallowedHost(msg)
django.core.exceptions.DisallowedHost: Invalid HTTP_HOST header: '45.61.136.175:7227'. You may need to add '45.61.136.175' to ALLOWED_HOSTS.
Bad Request: /45.61.136.175:7227
Invalid HTTP_HOST header: '45.61.136.175:7227'. You may need to add '45.61.136.175' to ALLOWED_HOSTS.
Traceback (most recent call last):
  File "/home/ubuntu/.local/lib/python3.10/site-packages/django/core/handlers/exception.py", line 55, in inner
    response = get_response(request)
  File "/home/ubuntu/.local/lib/python3.10/site-packages/django/utils/deprecation.py", line 133, in __call__
    response = self.process_request(request)
  File "/home/ubuntu/.local/lib/python3.10/site-packages/django/middleware/common.py", line 48, in process_request
    host = request.get_host()
  File "/home/ubuntu/.local/lib/python3.10/site-packages/django/http/request.py", line 151, in get_host
    raise DisallowedHost(msg)
django.core.exceptions.DisallowedHost: Invalid HTTP_HOST header: '45.61.136.175:7227'. You may need to add '45.61.136.175' to ALLOWED_HOSTS.
Bad Request: /45.61.136.175:7227
Invalid HTTP_HOST header: '193.149.189.126:7227'. You may need to add '193.149.189.126' to ALLOWED_HOSTS.
Traceback (most recent call last):
  File "/home/ubuntu/.local/lib/python3.10/site-packages/django/core/handlers/exception.py", line 55, in inner
    response = get_response(request)
  File "/home/ubuntu/.local/lib/python3.10/site-packages/django/utils/deprecation.py", line 133, in __call__
    response = self.process_request(request)
  File "/home/ubuntu/.local/lib/python3.10/site-packages/django/middleware/common.py", line 48, in process_request
    host = request.get_host()
  File "/home/ubuntu/.local/lib/python3.10/site-packages/django/http/request.py", line 151, in get_host
    raise DisallowedHost(msg)
django.core.exceptions.DisallowedHost: Invalid HTTP_HOST header: '193.149.189.126:7227'. You may need to add '193.149.189.126' to ALLOWED_HOSTS.
Bad Request: /193.149.189.126:7227
[10/Mar/2024 05:06:35] "GET / HTTP/1.1" 200 2
[10/Mar/2024 05:28:00] "GET / HTTP/1.1" 200 2
[10/Mar/2024 13:53:36] code 400, message Bad HTTP/0.9 request type ("\x16\x03\x01\x00{\x01\x00\x00w\x03\x03yÞ¼¾\x12B\x982\x88âÿF/«ÐÈ7RB\x97\x13Ó'e[q@×ÿµóã\x00\x00\x1aÀ/À+À\x11À\x07À\x13À")
[10/Mar/2024 13:53:36] You're accessing the development server over HTTPS, but it only supports HTTP.
Not Found: /login
[10/Mar/2024 14:00:04] "POST /login HTTP/1.1" 404 2711
Not Found: /.env
[10/Mar/2024 15:00:31] "GET /.env HTTP/1.1" 404 2707
[10/Mar/2024 15:26:31] "GET / HTTP/1.1" 200 2
[11/Mar/2024 05:19:26] "GET / HTTP/1.1" 200 2
[11/Mar/2024 05:40:08,776] - Broken pipe from ('104.152.52.227', 55577)
[11/Mar/2024 06:14:26] code 400, message Bad request syntax ('MGLNDD_18.223.137.231_8000')
[11/Mar/2024 06:14:26] "MGLNDD_18.223.137.231_8000" 400 -
Not Found: /.env
[11/Mar/2024 06:20:18] "GET /.env HTTP/1.1" 404 2707
[11/Mar/2024 07:02:50] "GET / HTTP/1.1" 200 2
Not Found: /.env
[11/Mar/2024 09:53:57] "GET /.env HTTP/1.1" 404 2707
[11/Mar/2024 11:50:16] "GET / HTTP/1.1" 200 2
Not Found: /favicon.ico
[11/Mar/2024 11:50:29] "GET /favicon.ico HTTP/1.1" 404 2728
Invalid HTTP_HOST header: 'api.ipify.org'. You may need to add 'api.ipify.org' to ALLOWED_HOSTS.
Traceback (most recent call last):
  File "/home/ubuntu/.local/lib/python3.10/site-packages/django/core/handlers/exception.py", line 55, in inner
    response = get_response(request)
  File "/home/ubuntu/.local/lib/python3.10/site-packages/django/utils/deprecation.py", line 133, in __call__
    response = self.process_request(request)
  File "/home/ubuntu/.local/lib/python3.10/site-packages/django/middleware/common.py", line 48, in process_request
    host = request.get_host()
  File "/home/ubuntu/.local/lib/python3.10/site-packages/django/http/request.py", line 151, in get_host
    raise DisallowedHost(msg)
django.core.exceptions.DisallowedHost: Invalid HTTP_HOST header: 'api.ipify.org'. You may need to add 'api.ipify.org' to ALLOWED_HOSTS.
Bad Request: /http:/api.ipify.org/
[11/Mar/2024 11:50:32] "GET http://api.ipify.org/?format=json HTTP/1.1" 400 63707
Invalid HTTP_HOST header: 'www.shadowserver.org'. You may need to add 'www.shadowserver.org' to ALLOWED_HOSTS.
Traceback (most recent call last):
  File "/home/ubuntu/.local/lib/python3.10/site-packages/django/core/handlers/exception.py", line 55, in inner
    response = get_response(request)
  File "/home/ubuntu/.local/lib/python3.10/site-packages/django/utils/deprecation.py", line 133, in __call__
    response = self.process_request(request)
  File "/home/ubuntu/.local/lib/python3.10/site-packages/django/middleware/common.py", line 48, in process_request
    host = request.get_host()
  File "/home/ubuntu/.local/lib/python3.10/site-packages/django/http/request.py", line 151, in get_host
    raise DisallowedHost(msg)
django.core.exceptions.DisallowedHost: Invalid HTTP_HOST header: 'www.shadowserver.org'. You may need to add 'www.shadowserver.org' to ALLOWED_HOSTS.
Bad Request: /www.shadowserver.org:443
[11/Mar/2024 11:50:35] "CONNECT www.shadowserver.org:443 HTTP/1.1" 400 63910
[11/Mar/2024 18:42:04] code 400, message Bad HTTP/0.9 request type ('\x16\x03\x01\x00{\x01\x00\x00w\x03\x03»¯¾\x8eç\x15\x13\x19qµ;X±¨\x95±]øK6å\x18}Öì¯Ð.<T,\x9b\x00\x00\x1aÀ/À+À\x11À\x07À\x13À')
[11/Mar/2024 18:42:04] You're accessing the development server over HTTPS, but it only supports HTTP.
[11/Mar/2024 19:21:07] code 400, message Bad request version ('À\x14À')
[11/Mar/2024 19:21:07] You're accessing the development server over HTTPS, but it only supports HTTP.
[11/Mar/2024 19:21:27] code 400, message Bad request version ('À\x14À')
[11/Mar/2024 19:21:27] You're accessing the development server over HTTPS, but it only supports HTTP.
Not Found: /favicon.ico
[11/Mar/2024 19:21:41] "GET /favicon.ico HTTP/1.1" 404 2728
[11/Mar/2024 19:21:54] code 400, message Bad HTTP/0.9 request type ('\x16\x03\x01\x00±\x01\x00\x00\xad\x03\x03\x01îg\x06çkY3ã¯)pùÈ\x07d×\x14\x90<W\x86~êv¦|4Äà\x8f$\x00\x00PÀ/À+À\x11À\x07À\x13À')
[11/Mar/2024 19:21:54] You're accessing the development server over HTTPS, but it only supports HTTP.
Not Found: /manage/account/login
[11/Mar/2024 19:22:08] "GET /manage/account/login HTTP/1.1" 404 2755
[11/Mar/2024 19:22:27] code 400, message Bad request version ('À\x14À')
[11/Mar/2024 19:22:27] You're accessing the development server over HTTPS, but it only supports HTTP.
[11/Mar/2024 19:22:41] "GET /admin/index.html HTTP/1.1" 302 0
[11/Mar/2024 19:23:05] code 400, message Bad request version ('À\x14À')
[11/Mar/2024 19:23:05] You're accessing the development server over HTTPS, but it only supports HTTP.
Not Found: /index.html
[11/Mar/2024 19:23:21] "GET /index.html HTTP/1.1" 404 2725
[11/Mar/2024 19:23:42] code 400, message Bad HTTP/0.9 request type ('\x16\x03\x01\x00±\x01\x00\x00\xad\x03\x03Xg\x03Ì\x8f\x18\x82CÖjÄù\x10S\x8bè¾ç\x18\x1a@m\x05Î&C{\x94\x00ð]Z\x00\x00PÀ/À+À\x11À\x07À\x13À')
[11/Mar/2024 19:23:42] You're accessing the development server over HTTPS, but it only supports HTTP.
Not Found: /+CSCOE+/logon.html
[11/Mar/2024 19:24:02] "GET /+CSCOE+/logon.html HTTP/1.1" 404 2749
[11/Mar/2024 19:24:29] code 400, message Bad request version ('À\x14À')
[11/Mar/2024 19:24:29] You're accessing the development server over HTTPS, but it only supports HTTP.
Not Found: /cgi-bin/login.cgi
[11/Mar/2024 19:24:44] "GET /cgi-bin/login.cgi HTTP/1.1" 404 2746
[11/Mar/2024 19:25:04] code 400, message Bad request syntax ('\x16\x03\x01\x00±\x01\x00\x00\xad\x03\x03')
[11/Mar/2024 19:25:04] You're accessing the development server over HTTPS, but it only supports HTTP.
Not Found: /logon.htm
[11/Mar/2024 19:25:19] "GET /logon.htm HTTP/1.1" 404 2722
[11/Mar/2024 19:25:38] code 400, message Bad HTTP/0.9 request type ('\x16\x03\x01\x00±\x01\x00\x00\xad\x03\x03\x9aP¢Þ1¦¯R\x9eÌ\x10Vn)\x9d±Ô^OÀª\x7f2ñ\x01\x8bnt,mÜ[\x00\x00PÀ/À+À\x11À\x07À\x13À')
[11/Mar/2024 19:25:38] You're accessing the development server over HTTPS, but it only supports HTTP.
Not Found: /login.jsp
[11/Mar/2024 19:25:52] "GET /login.jsp HTTP/1.1" 404 2722
[11/Mar/2024 19:26:11] code 400, message Bad request syntax ('\x16\x03\x01\x00±\x01\x00\x00\xad\x03\x03Jom')
[11/Mar/2024 19:26:11] You're accessing the development server over HTTPS, but it only supports HTTP.
Not Found: /doc/index.html
[11/Mar/2024 19:26:24] "GET /doc/index.html HTTP/1.1" 404 2737
[11/Mar/2024 19:26:41] code 400, message Bad request syntax ('\x16\x03\x01\x00±\x01\x00\x00\xad\x03\x039PSÿ6·uAuØ2\x13ó')
[11/Mar/2024 19:26:41] You're accessing the development server over HTTPS, but it only supports HTTP.
[11/Mar/2024 19:26:55] "GET / HTTP/1.1" 200 2
[11/Mar/2024 20:40:55] code 400, message Bad request syntax ('\x16\x03\x01\x00î\x01\x00\x00ê\x03\x033c\x80UØ\x16I¹å\x11\x87Üà')
[11/Mar/2024 20:40:55] You're accessing the development server over HTTPS, but it only supports HTTP.
[11/Mar/2024 20:40:55] code 400, message Bad HTTP/0.9 request type ("\x16\x03\x01\x00Ê\x01\x00\x00Æ\x03\x03'°.?ðì\x1at³û÷<d\x8fëÿ\x8d°\x15&#\x95QxÛ\x8dÜv\xadui½\x00\x00hÌ\x14Ì\x13À/À+À0À,À\x11À\x07À'À#À\x13À")
[11/Mar/2024 20:40:55] You're accessing the development server over HTTPS, but it only supports HTTP.
[11/Mar/2024 20:48:30] "GET / HTTP/1.1" 200 2
[12/Mar/2024 00:29:14] "GET / HTTP/1.1" 200 2
[12/Mar/2024 00:29:17,647] - Broken pipe from ('43.133.5.165', 59744)
[12/Mar/2024 01:41:21] "GET / HTTP/1.1" 200 2
Invalid HTTP_HOST header: 'api64.ipify.org:443'. You may need to add 'api64.ipify.org' to ALLOWED_HOSTS.
Traceback (most recent call last):
  File "/home/ubuntu/.local/lib/python3.10/site-packages/django/core/handlers/exception.py", line 55, in inner
    response = get_response(request)
  File "/home/ubuntu/.local/lib/python3.10/site-packages/django/utils/deprecation.py", line 133, in __call__
    response = self.process_request(request)
  File "/home/ubuntu/.local/lib/python3.10/site-packages/django/middleware/common.py", line 48, in process_request
    host = request.get_host()
  File "/home/ubuntu/.local/lib/python3.10/site-packages/django/http/request.py", line 151, in get_host
    raise DisallowedHost(msg)
django.core.exceptions.DisallowedHost: Invalid HTTP_HOST header: 'api64.ipify.org:443'. You may need to add 'api64.ipify.org' to ALLOWED_HOSTS.
Bad Request: /api64.ipify.org:443
[12/Mar/2024 02:49:04] "CONNECT api64.ipify.org:443 HTTP/1.1" 400 63260
[12/Mar/2024 03:22:56] code 400, message Bad HTTP/0.9 request type ('Z¥\x01')
[12/Mar/2024 03:22:56] "Z¥     " 400 -
[12/Mar/2024 04:33:08] code 400, message Bad request syntax ('MGLNDD_18.223.137.231_8000')
[12/Mar/2024 04:33:08] "MGLNDD_18.223.137.231_8000" 400 -
[12/Mar/2024 04:49:14] code 400, message Bad request syntax ('\x01\x01æ')
[12/Mar/2024 04:49:14] "æ" 400 -
Not Found: /.env
[12/Mar/2024 05:14:03] "GET /.env HTTP/1.1" 404 2707
[12/Mar/2024 06:36:15] code 400, message Bad request version ('OÑËÜ®Ëd')
[12/Mar/2024 06:36:15] "   TZ         .    I¨À )z» zÚf Ò~Uñi»©                ÃÐ¢|¦v½óOÑËÜ®Ëd" 400 -
[12/Mar/2024 10:55:29] code 400, message Bad request syntax ('MGLNDD_18.223.137.231_8000')
[12/Mar/2024 10:55:29] "MGLNDD_18.223.137.231_8000" 400 -
[12/Mar/2024 13:40:26] "GET / HTTP/1.1" 200 2
Not Found: /favicon.ico
[12/Mar/2024 13:40:58] "GET /favicon.ico HTTP/1.1" 404 2728
Invalid HTTP_HOST header: 'api.ipify.org'. You may need to add 'api.ipify.org' to ALLOWED_HOSTS.
Traceback (most recent call last):
  File "/home/ubuntu/.local/lib/python3.10/site-packages/django/core/handlers/exception.py", line 55, in inner
    response = get_response(request)
  File "/home/ubuntu/.local/lib/python3.10/site-packages/django/utils/deprecation.py", line 133, in __call__
    response = self.process_request(request)
  File "/home/ubuntu/.local/lib/python3.10/site-packages/django/middleware/common.py", line 48, in process_request
    host = request.get_host()
  File "/home/ubuntu/.local/lib/python3.10/site-packages/django/http/request.py", line 151, in get_host
    raise DisallowedHost(msg)
django.core.exceptions.DisallowedHost: Invalid HTTP_HOST header: 'api.ipify.org'. You may need to add 'api.ipify.org' to ALLOWED_HOSTS.
Bad Request: /http:/api.ipify.org/
[12/Mar/2024 13:41:22] "GET http://api.ipify.org/?format=json HTTP/1.1" 400 63716
Invalid HTTP_HOST header: 'www.shadowserver.org'. You may need to add 'www.shadowserver.org' to ALLOWED_HOSTS.
Traceback (most recent call last):
  File "/home/ubuntu/.local/lib/python3.10/site-packages/django/core/handlers/exception.py", line 55, in inner
    response = get_response(request)
  File "/home/ubuntu/.local/lib/python3.10/site-packages/django/utils/deprecation.py", line 133, in __call__
    response = self.process_request(request)
  File "/home/ubuntu/.local/lib/python3.10/site-packages/django/middleware/common.py", line 48, in process_request
    host = request.get_host()
  File "/home/ubuntu/.local/lib/python3.10/site-packages/django/http/request.py", line 151, in get_host
    raise DisallowedHost(msg)
django.core.exceptions.DisallowedHost: Invalid HTTP_HOST header: 'www.shadowserver.org'. You may need to add 'www.shadowserver.org' to ALLOWED_HOSTS.
Bad Request: /www.shadowserver.org:443
[12/Mar/2024 13:41:45] "CONNECT www.shadowserver.org:443 HTTP/1.1" 400 63919
[12/Mar/2024 18:17:03,157] - Broken pipe from ('199.45.154.19', 54836)
[12/Mar/2024 18:17:06] "GET / HTTP/1.1" 200 2
[12/Mar/2024 18:17:06,591] - Broken pipe from ('199.45.154.19', 41034)
[12/Mar/2024 18:17:09] "GET / HTTP/1.1" 200 2
[12/Mar/2024 18:17:10] code 505, message Invalid HTTP version (2.0)
[12/Mar/2024 18:17:10] "PRI * HTTP/2.0" 505 -
Not Found: /favicon.ico
[12/Mar/2024 18:17:10] "GET /favicon.ico HTTP/1.1" 404 2728
[12/Mar/2024 22:05:57] "GET / HTTP/1.1" 200 2
[13/Mar/2024 01:31:01] code 400, message Bad request version ('\x07Å\x1b¶\x15')
[13/Mar/2024 01:31:01] You're accessing the development server over HTTPS, but it only supports HTTP.
[13/Mar/2024 01:31:01] code 400, message Bad HTTP/0.9 request type ("\x16\x03\x01\x00Ê\x01\x00\x00Æ\x03\x03Ä÷Q\x1ahÛrîk9n\x94ã³6\x97¯í2ÔE#ËgÄÊû\x03î\x992°\x00\x00hÌ\x14Ì\x13À/À+À0À,À\x11À\x07À'À#À\x13À")
[13/Mar/2024 01:31:01] You're accessing the development server over HTTPS, but it only supports HTTP.
[13/Mar/2024 01:31:57,421] - Broken pipe from ('167.248.133.188', 40464)
[13/Mar/2024 01:32:01] "GET / HTTP/1.1" 200 2
[13/Mar/2024 01:32:01,332] - Broken pipe from ('167.248.133.188', 34586)
[13/Mar/2024 01:32:04] "GET / HTTP/1.1" 200 2
[13/Mar/2024 01:32:04] code 505, message Invalid HTTP version (2.0)
[13/Mar/2024 01:32:04] "PRI * HTTP/2.0" 505 -
Not Found: /favicon.ico
[13/Mar/2024 01:32:04] "GET /favicon.ico HTTP/1.1" 404 2728
[13/Mar/2024 01:46:52] "GET / HTTP/1.1" 200 2
Not Found: /aaa9
[13/Mar/2024 04:25:30] "GET /aaa9 HTTP/1.1" 404 2707
Not Found: /aab8
[13/Mar/2024 04:25:30] "GET /aab8 HTTP/1.1" 404 2707
[13/Mar/2024 04:25:30] "GET / HTTP/1.1" 200 2
[13/Mar/2024 05:48:29] "GET / HTTP/1.1" 200 2
[13/Mar/2024 06:17:37] "GET / HTTP/1.1" 200 2
Not Found: /favicon.ico
[13/Mar/2024 06:17:47] "GET /favicon.ico HTTP/1.1" 404 2728
Invalid HTTP_HOST header: 'api.ipify.org'. You may need to add 'api.ipify.org' to ALLOWED_HOSTS.
Traceback (most recent call last):
  File "/home/ubuntu/.local/lib/python3.10/site-packages/django/core/handlers/exception.py", line 55, in inner
    response = get_response(request)
  File "/home/ubuntu/.local/lib/python3.10/site-packages/django/utils/deprecation.py", line 133, in __call__
    response = self.process_request(request)
  File "/home/ubuntu/.local/lib/python3.10/site-packages/django/middleware/common.py", line 48, in process_request
    host = request.get_host()
  File "/home/ubuntu/.local/lib/python3.10/site-packages/django/http/request.py", line 151, in get_host
    raise DisallowedHost(msg)
django.core.exceptions.DisallowedHost: Invalid HTTP_HOST header: 'api.ipify.org'. You may need to add 'api.ipify.org' to ALLOWED_HOSTS.
Bad Request: /http:/api.ipify.org/
[13/Mar/2024 06:17:52] "GET http://api.ipify.org/?format=json HTTP/1.1" 400 63652
Invalid HTTP_HOST header: 'www.shadowserver.org'. You may need to add 'www.shadowserver.org' to ALLOWED_HOSTS.
Traceback (most recent call last):
  File "/home/ubuntu/.local/lib/python3.10/site-packages/django/core/handlers/exception.py", line 55, in inner
    response = get_response(request)
  File "/home/ubuntu/.local/lib/python3.10/site-packages/django/utils/deprecation.py", line 133, in __call__
    response = self.process_request(request)
  File "/home/ubuntu/.local/lib/python3.10/site-packages/django/middleware/common.py", line 48, in process_request
    host = request.get_host()
  File "/home/ubuntu/.local/lib/python3.10/site-packages/django/http/request.py", line 151, in get_host
    raise DisallowedHost(msg)
django.core.exceptions.DisallowedHost: Invalid HTTP_HOST header: 'www.shadowserver.org'. You may need to add 'www.shadowserver.org' to ALLOWED_HOSTS.
Bad Request: /www.shadowserver.org:443
[13/Mar/2024 06:17:55] "CONNECT www.shadowserver.org:443 HTTP/1.1" 400 63855
[13/Mar/2024 06:48:02] code 400, message Bad request syntax ('MGLNDD_18.223.137.231_8000')
[13/Mar/2024 06:48:02] "MGLNDD_18.223.137.231_8000" 400 -
[13/Mar/2024 08:04:46] "GET / HTTP/1.1" 200 2
[13/Mar/2024 08:04:47] code 400, message Bad request version ('À\x13À')
[13/Mar/2024 08:04:47] You're accessing the development server over HTTPS, but it only supports HTTP.
[13/Mar/2024 08:04:47] code 400, message Bad HTTP/0.9 request type ('t3')
[13/Mar/2024 08:04:47] "t3 12.1.2" 400 -
[13/Mar/2024 08:44:39] "GET / HTTP/1.1" 200 2
[13/Mar/2024 10:19:51] "GET / HTTP/1.1" 200 2
Not Found: /favicon.ico
[13/Mar/2024 10:19:52] "GET /favicon.ico HTTP/1.1" 404 2728
Not Found: /robots.txt
[13/Mar/2024 10:19:52] "GET /robots.txt HTTP/1.1" 404 2725
Not Found: /sitemap.xml
[13/Mar/2024 10:19:52] "GET /sitemap.xml HTTP/1.1" 404 2728
[13/Mar/2024 13:29:57] code 400, message Bad HTTP/0.9 request type ('\x16\x03\x01\x00u\x01\x00\x00q\x03\x03dÉC\x12')
[13/Mar/2024 13:29:57] You're accessing the development server over HTTPS, but it only supports HTTP.
[13/Mar/2024 15:29:33] "GET / HTTP/1.1" 200 2
[13/Mar/2024 16:26:01] code 400, message Bad request version ('À\x14À')
[13/Mar/2024 16:26:01] You're accessing the development server over HTTPS, but it only supports HTTP.
Not Found: /.env
[13/Mar/2024 18:31:14] "GET /.env HTTP/1.1" 404 2707
[13/Mar/2024 19:11:31] code 400, message Bad request syntax ('\x01\x01æ')
[13/Mar/2024 19:11:31] "æ" 400 -
[13/Mar/2024 20:20:14] code 400, message Bad request version ('À\x13À')
[13/Mar/2024 20:20:14] You're accessing the development server over HTTPS, but it only supports HTTP.
[13/Mar/2024 20:20:15] code 400, message Bad request version ('À(À$À\x14À')
[13/Mar/2024 20:20:15] You're accessing the development server over HTTPS, but it only supports HTTP.
Not Found: /.env
[13/Mar/2024 21:39:39] "GET /.env HTTP/1.1" 404 2707
[14/Mar/2024 03:50:28] "GET / HTTP/1.1" 200 2
Not Found: /.env
[14/Mar/2024 05:05:15] "GET /.env HTTP/1.1" 404 2707
[14/Mar/2024 07:07:40] code 400, message Bad request version ('À\x14À')
[14/Mar/2024 07:07:40] You're accessing the development server over HTTPS, but it only supports HTTP.
[14/Mar/2024 07:42:37] "GET / HTTP/1.1" 200 2
Not Found: /.env
[14/Mar/2024 09:16:45] "GET /.env HTTP/1.1" 404 2707
[14/Mar/2024 10:10:30] code 400, message Bad request syntax ('MGLNDD_18.223.137.231_8000')
[14/Mar/2024 10:10:30] "MGLNDD_18.223.137.231_8000" 400 -
[14/Mar/2024 10:27:23,729] - Broken pipe from ('167.94.138.124', 52500)
[14/Mar/2024 10:27:26] "GET / HTTP/1.1" 200 2
[14/Mar/2024 10:27:26,759] - Broken pipe from ('167.94.138.124', 35028)
[14/Mar/2024 10:27:29] "GET / HTTP/1.1" 200 2
[14/Mar/2024 10:27:29] code 505, message Invalid HTTP version (2.0)
[14/Mar/2024 10:27:29] "PRI * HTTP/2.0" 505 -
Not Found: /favicon.ico
[14/Mar/2024 10:27:29] "GET /favicon.ico HTTP/1.1" 404 2728
[14/Mar/2024 11:45:37] code 400, message Bad request version ('À\x13À')
[14/Mar/2024 11:45:37] You're accessing the development server over HTTPS, but it only supports HTTP.
[14/Mar/2024 11:45:41] "GET / HTTP/1.1" 200 2
[14/Mar/2024 13:56:48] "GET / HTTP/1.1" 200 2
Not Found: /favicon.ico
[14/Mar/2024 13:56:59] "GET /favicon.ico HTTP/1.1" 404 2728
Invalid HTTP_HOST header: 'api.ipify.org'. You may need to add 'api.ipify.org' to ALLOWED_HOSTS.
Traceback (most recent call last):
  File "/home/ubuntu/.local/lib/python3.10/site-packages/django/core/handlers/exception.py", line 55, in inner
    response = get_response(request)
  File "/home/ubuntu/.local/lib/python3.10/site-packages/django/utils/deprecation.py", line 133, in __call__
    response = self.process_request(request)
  File "/home/ubuntu/.local/lib/python3.10/site-packages/django/middleware/common.py", line 48, in process_request
    host = request.get_host()
  File "/home/ubuntu/.local/lib/python3.10/site-packages/django/http/request.py", line 151, in get_host
    raise DisallowedHost(msg)
django.core.exceptions.DisallowedHost: Invalid HTTP_HOST header: 'api.ipify.org'. You may need to add 'api.ipify.org' to ALLOWED_HOSTS.
Bad Request: /http:/api.ipify.org/
[14/Mar/2024 13:57:09] "GET http://api.ipify.org/?format=json HTTP/1.1" 400 63710
Invalid HTTP_HOST header: 'www.shadowserver.org'. You may need to add 'www.shadowserver.org' to ALLOWED_HOSTS.
Traceback (most recent call last):
  File "/home/ubuntu/.local/lib/python3.10/site-packages/django/core/handlers/exception.py", line 55, in inner
    response = get_response(request)
  File "/home/ubuntu/.local/lib/python3.10/site-packages/django/utils/deprecation.py", line 133, in __call__
    response = self.process_request(request)
  File "/home/ubuntu/.local/lib/python3.10/site-packages/django/middleware/common.py", line 48, in process_request
    host = request.get_host()
  File "/home/ubuntu/.local/lib/python3.10/site-packages/django/http/request.py", line 151, in get_host
    raise DisallowedHost(msg)
django.core.exceptions.DisallowedHost: Invalid HTTP_HOST header: 'www.shadowserver.org'. You may need to add 'www.shadowserver.org' to ALLOWED_HOSTS.
Bad Request: /www.shadowserver.org:443
[14/Mar/2024 13:57:12] "CONNECT www.shadowserver.org:443 HTTP/1.1" 400 63913
[14/Mar/2024 15:20:27] code 400, message Bad request syntax ('\x01\x01æ')
[14/Mar/2024 15:20:27] "æ" 400 -
Not Found: /.DS_Store
[14/Mar/2024 19:16:32] "GET /.DS_Store HTTP/1.1" 404 2722
[14/Mar/2024 20:08:58] "GET / HTTP/1.1" 200 2
[15/Mar/2024 00:36:34] "GET / HTTP/1.1" 200 5085
Not Found: /favicon.ico
[15/Mar/2024 00:37:10] "GET /favicon.ico HTTP/1.1" 404 2728
Not Found: /.vscode/sftp.json
[15/Mar/2024 00:52:32] "GET /.vscode/sftp.json HTTP/1.1" 404 2746
[15/Mar/2024 02:52:06] code 400, message Bad request version ('F\x07\x00tsXrcsXYs9\x00\x00\x00\x00\x00\x00\x00\x00\x00\x00\x00\x00\x00\x00\x00\x00\x00\x00\x00\x00\x00\x00bbXcsXctst\x00\x00\x00\x00\x00\x00')
[15/Mar/2024 02:52:06] "   TZ          0I    ¨À )t F tsXrcsXYs9                      bbXcsXctst      " 400 -
[15/Mar/2024 03:02:15] "GET / HTTP/1.1" 200 2
[15/Mar/2024 04:08:56] "GET / HTTP/1.1" 200 2
[15/Mar/2024 04:24:40] code 400, message Bad request version ('À\x14À')
[15/Mar/2024 04:24:40] You're accessing the development server over HTTPS, but it only supports HTTP.
[15/Mar/2024 07:34:32] code 400, message Bad request syntax ('MGLNDD_18.223.137.231_8000')
[15/Mar/2024 07:34:32] "MGLNDD_18.223.137.231_8000" 400 -
Not Found: /.git/config
[15/Mar/2024 07:52:31] "GET /.git/config HTTP/1.1" 404 2728
[15/Mar/2024 08:57:25] code 400, message Bad request version ('À\x13À')
[15/Mar/2024 08:57:25] You're accessing the development server over HTTPS, but it only supports HTTP.
[15/Mar/2024 08:57:26] code 400, message Bad request version ('À(À$À\x14À')
[15/Mar/2024 08:57:26] You're accessing the development server over HTTPS, but it only supports HTTP.
Invalid HTTP_HOST header: 'httpbin.org'. You may need to add 'httpbin.org' to ALLOWED_HOSTS.
Traceback (most recent call last):
  File "/home/ubuntu/.local/lib/python3.10/site-packages/django/core/handlers/exception.py", line 55, in inner
    response = get_response(request)
  File "/home/ubuntu/.local/lib/python3.10/site-packages/django/utils/deprecation.py", line 133, in __call__
    response = self.process_request(request)
  File "/home/ubuntu/.local/lib/python3.10/site-packages/django/middleware/common.py", line 48, in process_request
    host = request.get_host()
  File "/home/ubuntu/.local/lib/python3.10/site-packages/django/http/request.py", line 151, in get_host
    raise DisallowedHost(msg)
django.core.exceptions.DisallowedHost: Invalid HTTP_HOST header: 'httpbin.org'. You may need to add 'httpbin.org' to ALLOWED_HOSTS.
Bad Request: /http:/httpbin.org/ip
[15/Mar/2024 10:09:13] "GET http://httpbin.org/ip HTTP/1.1" 400 63414
[15/Mar/2024 10:26:33] "GET / HTTP/1.1" 200 2
Not Found: /favicon.ico
[15/Mar/2024 10:26:42] "GET /favicon.ico HTTP/1.1" 404 2728
Invalid HTTP_HOST header: 'api.ipify.org'. You may need to add 'api.ipify.org' to ALLOWED_HOSTS.
Traceback (most recent call last):
  File "/home/ubuntu/.local/lib/python3.10/site-packages/django/core/handlers/exception.py", line 55, in inner
    response = get_response(request)
  File "/home/ubuntu/.local/lib/python3.10/site-packages/django/utils/deprecation.py", line 133, in __call__
    response = self.process_request(request)
  File "/home/ubuntu/.local/lib/python3.10/site-packages/django/middleware/common.py", line 48, in process_request
    host = request.get_host()
  File "/home/ubuntu/.local/lib/python3.10/site-packages/django/http/request.py", line 151, in get_host
    raise DisallowedHost(msg)
django.core.exceptions.DisallowedHost: Invalid HTTP_HOST header: 'api.ipify.org'. You may need to add 'api.ipify.org' to ALLOWED_HOSTS.
Bad Request: /http:/api.ipify.org/
[15/Mar/2024 10:26:45] "GET http://api.ipify.org/?format=json HTTP/1.1" 400 63772
Invalid HTTP_HOST header: 'www.shadowserver.org'. You may need to add 'www.shadowserver.org' to ALLOWED_HOSTS.
Traceback (most recent call last):
  File "/home/ubuntu/.local/lib/python3.10/site-packages/django/core/handlers/exception.py", line 55, in inner
    response = get_response(request)
  File "/home/ubuntu/.local/lib/python3.10/site-packages/django/utils/deprecation.py", line 133, in __call__
    response = self.process_request(request)
  File "/home/ubuntu/.local/lib/python3.10/site-packages/django/middleware/common.py", line 48, in process_request
    host = request.get_host()
  File "/home/ubuntu/.local/lib/python3.10/site-packages/django/http/request.py", line 151, in get_host
    raise DisallowedHost(msg)
django.core.exceptions.DisallowedHost: Invalid HTTP_HOST header: 'www.shadowserver.org'. You may need to add 'www.shadowserver.org' to ALLOWED_HOSTS.
Bad Request: /www.shadowserver.org:443
[15/Mar/2024 10:26:48] "CONNECT www.shadowserver.org:443 HTTP/1.1" 400 63975
[15/Mar/2024 17:17:48] code 400, message Bad HTTP/0.9 request type ('Z¥\x01')
[15/Mar/2024 17:17:48] "Z¥     " 400 -
Invalid HTTP_HOST header: 'example.com:80'. You may need to add 'example.com' to ALLOWED_HOSTS.
Traceback (most recent call last):
  File "/home/ubuntu/.local/lib/python3.10/site-packages/django/core/handlers/exception.py", line 55, in inner
    response = get_response(request)
  File "/home/ubuntu/.local/lib/python3.10/site-packages/django/utils/deprecation.py", line 133, in __call__
    response = self.process_request(request)
  File "/home/ubuntu/.local/lib/python3.10/site-packages/django/middleware/common.py", line 48, in process_request
    host = request.get_host()
  File "/home/ubuntu/.local/lib/python3.10/site-packages/django/http/request.py", line 151, in get_host
    raise DisallowedHost(msg)
django.core.exceptions.DisallowedHost: Invalid HTTP_HOST header: 'example.com:80'. You may need to add 'example.com' to ALLOWED_HOSTS.
Bad Request: /example.com:80
[15/Mar/2024 17:38:50] "CONNECT example.com:80 HTTP/1.1" 400 63103
[15/Mar/2024 17:39:05] code 400, message Bad request syntax ('\x05\x01\x00')
[15/Mar/2024 17:39:05] " " 400 -
[15/Mar/2024 17:39:05] code 400, message Bad request syntax ('\x04\x01\x00P\x00\x00\x00\x01\x00example.com\x00')
[15/Mar/2024 17:39:05] " P    example.com " 400 -
[15/Mar/2024 22:10:55] "GET / HTTP/1.1" 200 2
[16/Mar/2024 00:16:43] "GET / HTTP/1.1" 200 2
[16/Mar/2024 03:09:37] code 400, message Bad request version ('À\x14À')
[16/Mar/2024 03:09:37] You're accessing the development server over HTTPS, but it only supports HTTP.
[16/Mar/2024 03:48:15] code 400, message Bad request version ('À\x13À')
[16/Mar/2024 03:48:15] You're accessing the development server over HTTPS, but it only supports HTTP.
[16/Mar/2024 03:48:15] code 400, message Bad request version ('À(À$À\x14À')
[16/Mar/2024 03:48:15] You're accessing the development server over HTTPS, but it only supports HTTP.
[16/Mar/2024 04:29:31] code 400, message Bad request syntax ('MGLNDD_18.223.137.231_8000')
[16/Mar/2024 04:29:31] "MGLNDD_18.223.137.231_8000" 400 -
[16/Mar/2024 05:09:14] "GET / HTTP/1.1" 200 2
[16/Mar/2024 05:09:15] code 400, message Bad request version ('À\x13À')
[16/Mar/2024 05:09:15] You're accessing the development server over HTTPS, but it only supports HTTP.
[16/Mar/2024 05:09:16] code 400, message Bad HTTP/0.9 request type ('t3')
[16/Mar/2024 05:09:16] "t3 12.1.2" 400 -
[16/Mar/2024 05:09:35] "GET / HTTP/1.1" 200 2
Not Found: /favicon.ico
[16/Mar/2024 05:09:35] "GET /favicon.ico HTTP/1.1" 404 2728
Not Found: /sitemap.xml
[16/Mar/2024 05:09:36] "GET /sitemap.xml HTTP/1.1" 404 2728
Not Found: /robots.txt
[16/Mar/2024 05:09:36] "GET /robots.txt HTTP/1.1" 404 2725
[16/Mar/2024 09:11:52] code 400, message Bad HTTP/0.9 request type ('\x16\x03\x01\x00{\x01\x00\x00w\x03\x03\x7fv\x92\x8cº3¿Üàì\x06ò÷ýØÏ,\x14Á\x9d\x8do\x01X\x04-£\x82\x03E»\\\x00\x00\x1aÀ/À+À\x11À\x07À\x13À')
[16/Mar/2024 09:11:52] You're accessing the development server over HTTPS, but it only supports HTTP.
[16/Mar/2024 09:15:26] code 400, message Bad request version ('À\x14À')
[16/Mar/2024 09:15:26] You're accessing the development server over HTTPS, but it only supports HTTP.
Not Found: /favicon.ico
[16/Mar/2024 09:18:14] "GET /favicon.ico HTTP/1.1" 404 2728
[16/Mar/2024 09:20:37] code 400, message Bad HTTP/0.9 request type ('\x16\x03\x01\x00±\x01\x00\x00\xad\x03\x03\x8e;C:6\x87ÔEþwû\x06¦¢tpQ_Ô=°WP\x9aÒ&m\x9cÎ×çÇ\x00\x00PÀ/À+À\x11À\x07À\x13À')
[16/Mar/2024 09:20:37] You're accessing the development server over HTTPS, but it only supports HTTP.
Not Found: /manage/account/login
[16/Mar/2024 09:23:43] "GET /manage/account/login HTTP/1.1" 404 2755
[16/Mar/2024 09:27:28] code 400, message Bad request version ('À\x14À')
[16/Mar/2024 09:27:28] You're accessing the development server over HTTPS, but it only supports HTTP.
[16/Mar/2024 09:30:58] "GET /admin/index.html HTTP/1.1" 302 0
[16/Mar/2024 09:35:18] code 400, message Bad request version ('À\x14À')
[16/Mar/2024 09:35:18] You're accessing the development server over HTTPS, but it only supports HTTP.
[16/Mar/2024 09:42:54] code 400, message Bad request version ('À\x14À')
[16/Mar/2024 09:42:54] You're accessing the development server over HTTPS, but it only supports HTTP.
[16/Mar/2024 09:50:30] code 400, message Bad request version ('À\x14À')
[16/Mar/2024 09:50:30] You're accessing the development server over HTTPS, but it only supports HTTP.
[16/Mar/2024 09:58:30] code 400, message Bad request version ('À\x14À')
[16/Mar/2024 09:58:30] You're accessing the development server over HTTPS, but it only supports HTTP.
[16/Mar/2024 09:59:18] "GET / HTTP/1.1" 200 2
Invalid HTTP_HOST header: 'api.ipify.org'. You may need to add 'api.ipify.org' to ALLOWED_HOSTS.
Traceback (most recent call last):
  File "/home/ubuntu/.local/lib/python3.10/site-packages/django/core/handlers/exception.py", line 55, in inner
    response = get_response(request)
  File "/home/ubuntu/.local/lib/python3.10/site-packages/django/utils/deprecation.py", line 133, in __call__
    response = self.process_request(request)
  File "/home/ubuntu/.local/lib/python3.10/site-packages/django/middleware/common.py", line 48, in process_request
    host = request.get_host()
  File "/home/ubuntu/.local/lib/python3.10/site-packages/django/http/request.py", line 151, in get_host
    raise DisallowedHost(msg)
django.core.exceptions.DisallowedHost: Invalid HTTP_HOST header: 'api.ipify.org'. You may need to add 'api.ipify.org' to ALLOWED_HOSTS.
Bad Request: /http:/api.ipify.org/
[16/Mar/2024 09:59:43] "GET http://api.ipify.org/?format=json HTTP/1.1" 400 63772
Invalid HTTP_HOST header: 'www.shadowserver.org'. You may need to add 'www.shadowserver.org' to ALLOWED_HOSTS.
Traceback (most recent call last):
  File "/home/ubuntu/.local/lib/python3.10/site-packages/django/core/handlers/exception.py", line 55, in inner
    response = get_response(request)
  File "/home/ubuntu/.local/lib/python3.10/site-packages/django/utils/deprecation.py", line 133, in __call__
    response = self.process_request(request)
  File "/home/ubuntu/.local/lib/python3.10/site-packages/django/middleware/common.py", line 48, in process_request
    host = request.get_host()
  File "/home/ubuntu/.local/lib/python3.10/site-packages/django/http/request.py", line 151, in get_host
    raise DisallowedHost(msg)
django.core.exceptions.DisallowedHost: Invalid HTTP_HOST header: 'www.shadowserver.org'. You may need to add 'www.shadowserver.org' to ALLOWED_HOSTS.
Bad Request: /www.shadowserver.org:443
[16/Mar/2024 09:59:54] "CONNECT www.shadowserver.org:443 HTTP/1.1" 400 63975
Not Found: /logon.htm
[16/Mar/2024 10:01:54] "GET /logon.htm HTTP/1.1" 404 2722
Not Found: /login.jsp
[16/Mar/2024 10:09:34] "GET /login.jsp HTTP/1.1" 404 2722
Not Found: /doc/index.html
[16/Mar/2024 10:17:22] "GET /doc/index.html HTTP/1.1" 404 2737
[16/Mar/2024 10:24:58] "GET / HTTP/1.1" 200 2
Not Found: /.DS_Store
[16/Mar/2024 16:40:18] "GET /.DS_Store HTTP/1.1" 404 2722
[16/Mar/2024 18:11:21] code 400, message Bad HTTP/0.9 request type ('\x00\x00\x00')
[16/Mar/2024 18:11:21] "    c                           " 400 -
[16/Mar/2024 18:22:18] code 400, message Bad request syntax ('JDWP-Handshake')
[16/Mar/2024 18:22:18] "JDWP-Handshake" 400 -
[16/Mar/2024 20:20:31] code 400, message Bad HTTP/0.9 request type ('\x00\x00\x00')
[16/Mar/2024 20:20:31] "    c                           " 400 -
[16/Mar/2024 21:06:18] code 400, message Bad request syntax ('\x01\x01æ')
[16/Mar/2024 21:06:18] "æ" 400 -
Not Found: /.vscode/sftp.json
[16/Mar/2024 21:50:15] "GET /.vscode/sftp.json HTTP/1.1" 404 2746
[16/Mar/2024 21:56:28] code 400, message Bad HTTP/0.9 request type ('\x00\x00\x00')
[16/Mar/2024 21:56:28] "    c                           " 400 -
[16/Mar/2024 23:14:22] code 400, message Bad request version ('À\x14À')
[16/Mar/2024 23:14:22] You're accessing the development server over HTTPS, but it only supports HTTP.
[16/Mar/2024 23:31:22] code 400, message Bad HTTP/0.9 request type ('\x00\x00\x00')
[16/Mar/2024 23:31:22] "    c                           " 400 -
[16/Mar/2024 23:44:52] code 400, message Bad request version ('À\x14À')
[16/Mar/2024 23:44:52] You're accessing the development server over HTTPS, but it only supports HTTP.
[17/Mar/2024 01:01:36] "GET / HTTP/1.1" 200 2
Not Found: /.git/config
[17/Mar/2024 01:36:35] "GET /.git/config HTTP/1.1" 404 2728
[17/Mar/2024 04:11:47] "GET / HTTP/1.1" 200 2
[17/Mar/2024 11:30:00] code 400, message Bad HTTP/0.9 request type ('\x00\x00\x00')
[17/Mar/2024 11:30:00] "    c                           " 400 -
[17/Mar/2024 11:34:11] code 400, message Bad HTTP/0.9 request type ('\x00\x00\x00')
[17/Mar/2024 11:34:11] "    c                           " 400 -
[17/Mar/2024 12:02:23] "GET / HTTP/1.1" 200 2
[17/Mar/2024 12:02:33] code 505, message Invalid HTTP version (2.0)
[17/Mar/2024 12:02:33] "PRI * HTTP/2.0" 505 -
Not Found: /favicon.ico
[17/Mar/2024 12:02:33] "GET /favicon.ico HTTP/1.1" 404 2728
[17/Mar/2024 15:23:47] "GET / HTTP/1.1" 200 2
[17/Mar/2024 15:23:57] code 505, message Invalid HTTP version (2.0)
[17/Mar/2024 15:23:57] "PRI * HTTP/2.0" 505 -
Not Found: /favicon.ico
[17/Mar/2024 15:23:57] "GET /favicon.ico HTTP/1.1" 404 2728
[17/Mar/2024 18:47:16] code 400, message Bad request syntax ('\x01\x01æ')
[17/Mar/2024 18:47:16] "æ" 400 -
[17/Mar/2024 20:15:29] code 400, message Bad request version ('À\x14À')
[17/Mar/2024 20:15:29] You're accessing the development server over HTTPS, but it only supports HTTP.
[17/Mar/2024 21:56:41,136] - Broken pipe from ('104.152.52.90', 52562)
[18/Mar/2024 04:52:50] "GET / HTTP/1.1" 200 2
[18/Mar/2024 04:58:31] "GET / HTTP/1.1" 200 2
[18/Mar/2024 06:11:24] code 400, message Bad request syntax ('MGLNDD_18.223.137.231_8000')
[18/Mar/2024 06:11:24] "MGLNDD_18.223.137.231_8000" 400 -
Not Found: /.env
[18/Mar/2024 08:11:17] "GET /.env HTTP/1.1" 404 2707
[18/Mar/2024 08:14:19] code 400, message Bad request version ('À\x13À')
[18/Mar/2024 08:14:19] You're accessing the development server over HTTPS, but it only supports HTTP.
[18/Mar/2024 08:14:20] code 400, message Bad request version ('À(À$À\x14À')
[18/Mar/2024 08:14:20] You're accessing the development server over HTTPS, but it only supports HTTP.
[18/Mar/2024 09:39:59] "GET / HTTP/1.1" 200 2
Not Found: /.env
[18/Mar/2024 09:57:39] "GET /.env HTTP/1.1" 404 2707
[18/Mar/2024 10:35:51] code 400, message Bad request version ('À\x14À')
[18/Mar/2024 10:35:51] You're accessing the development server over HTTPS, but it only supports HTTP.
[18/Mar/2024 11:10:44] "GET / HTTP/1.1" 200 2
Not Found: /favicon.ico
[18/Mar/2024 11:11:20] "GET /favicon.ico HTTP/1.1" 404 2728
Invalid HTTP_HOST header: 'api.ipify.org'. You may need to add 'api.ipify.org' to ALLOWED_HOSTS.
Traceback (most recent call last):
  File "/home/ubuntu/.local/lib/python3.10/site-packages/django/core/handlers/exception.py", line 55, in inner
    response = get_response(request)
  File "/home/ubuntu/.local/lib/python3.10/site-packages/django/utils/deprecation.py", line 133, in __call__
    response = self.process_request(request)
  File "/home/ubuntu/.local/lib/python3.10/site-packages/django/middleware/common.py", line 48, in process_request
    host = request.get_host()
  File "/home/ubuntu/.local/lib/python3.10/site-packages/django/http/request.py", line 151, in get_host
    raise DisallowedHost(msg)
django.core.exceptions.DisallowedHost: Invalid HTTP_HOST header: 'api.ipify.org'. You may need to add 'api.ipify.org' to ALLOWED_HOSTS.
Bad Request: /http:/api.ipify.org/
[18/Mar/2024 11:11:43] "GET http://api.ipify.org/?format=json HTTP/1.1" 400 63806
Invalid HTTP_HOST header: 'www.shadowserver.org'. You may need to add 'www.shadowserver.org' to ALLOWED_HOSTS.
Traceback (most recent call last):
  File "/home/ubuntu/.local/lib/python3.10/site-packages/django/core/handlers/exception.py", line 55, in inner
    response = get_response(request)
  File "/home/ubuntu/.local/lib/python3.10/site-packages/django/utils/deprecation.py", line 133, in __call__
    response = self.process_request(request)
  File "/home/ubuntu/.local/lib/python3.10/site-packages/django/middleware/common.py", line 48, in process_request
    host = request.get_host()
  File "/home/ubuntu/.local/lib/python3.10/site-packages/django/http/request.py", line 151, in get_host
    raise DisallowedHost(msg)
django.core.exceptions.DisallowedHost: Invalid HTTP_HOST header: 'www.shadowserver.org'. You may need to add 'www.shadowserver.org' to ALLOWED_HOSTS.
Bad Request: /www.shadowserver.org:443
[18/Mar/2024 11:12:05] "CONNECT www.shadowserver.org:443 HTTP/1.1" 400 64009
[18/Mar/2024 13:08:38] code 400, message Bad HTTP/0.9 request type ('\x00\x00\x00')
[18/Mar/2024 13:08:38] "    c                           " 400 -
[18/Mar/2024 14:16:34] code 400, message Bad HTTP/0.9 request type ('\\x01\\x00\\x00\\x00')
[18/Mar/2024 14:16:34] "\x01\x00\x00\x00 \xbf\x02\x00\x88\x13\x00\x00\x87\x00\x00\x00NIMABIJIAN\x04\x03\x00\x00{\x99Caig\x9c\x03\xc7eB\xc5\t\xc1\x18a\x11\x1a\x91\x1f\x02\tcof\x91\xc0\x80sJ5\xd2\x80\xe6\x9a~\xb9\xc7\x83^\x96\xeeN\x16\x96\x96&\xe6\x03\xea\xbc\x81\x02=\xac\x10\xfa?7\x03\xc3\xdf\xf7\xe4\x98`p\xe6\x8d\xc1\xa9\x8d\xc6\x06\xdb\xaf\x91\xe7\x82s\xf7\x14H\xd4\xe1W\x9a\x93C\x9e]\xa4\x01#\x03#\x03]\x03c]CC\x05C\x03+S\x03b\xf4\x00\x00/\x9e\x16E" 400 -
Not Found: /favicon.ico
[18/Mar/2024 14:16:34] "GET /favicon.ico HTTP/1.1" 404 2728
Not Found: /robots.txt
[18/Mar/2024 14:16:35] "GET /robots.txt HTTP/1.1" 404 2725
Not Found: /.well-known/security.txt
[18/Mar/2024 14:16:36] "GET /.well-known/security.txt HTTP/1.1" 404 2767
[18/Mar/2024 15:58:46] code 400, message Bad HTTP/0.9 request type ('\x00\x00\x00')
[18/Mar/2024 15:58:46] "    c                           " 400 -
[18/Mar/2024 19:01:35] "GET / HTTP/1.1" 200 2
[18/Mar/2024 19:58:18] code 400, message Bad request syntax ('JDWP-Handshake')
[18/Mar/2024 19:58:18] "JDWP-Handshake" 400 -
[18/Mar/2024 22:42:21] "GET / HTTP/1.1" 200 2
[18/Mar/2024 22:42:23] code 400, message Bad request version ('<ËæAIâ¦¨\x96M¼\x92ç¿z#Í=of\x16\x93ÖgjÊo\x00ðã\x7f$\x03\x13F\x19¶¢»')
[18/Mar/2024 22:42:23] You're accessing the development server over HTTPS, but it only supports HTTP.
[18/Mar/2024 22:42:23] code 400, message Bad request version ('\x06\x01º\x05nH$')
[18/Mar/2024 22:42:23] You're accessing the development server over HTTPS, but it only supports HTTP.
[18/Mar/2024 22:42:23] "GET / HTTP/1.1" 200 5085
[18/Mar/2024 22:42:23] "GET /static/rest_framework/css/bootstrap.min.css HTTP/1.1" 200 121457
[18/Mar/2024 22:42:23] "GET /static/rest_framework/css/default.css HTTP/1.1" 200 1152
[18/Mar/2024 22:42:23] "GET /static/rest_framework/css/bootstrap-tweaks.css HTTP/1.1" 200 3385
[18/Mar/2024 22:42:23] "GET /static/rest_framework/css/prettify.css HTTP/1.1" 200 817
[18/Mar/2024 22:42:23] "GET /static/rest_framework/js/jquery-3.5.1.min.js HTTP/1.1" 200 89476
[18/Mar/2024 22:42:23] "GET /static/rest_framework/js/ajax-form.js HTTP/1.1" 200 3597
[18/Mar/2024 22:42:23] "GET /static/rest_framework/js/csrf.js HTTP/1.1" 200 1719
[18/Mar/2024 22:42:23] "GET /static/rest_framework/js/bootstrap.min.js HTTP/1.1" 200 39680
[18/Mar/2024 22:42:23] "GET /static/rest_framework/js/prettify-min.js HTTP/1.1" 200 13632
[18/Mar/2024 22:42:23] "GET /static/rest_framework/js/default.js HTTP/1.1" 200 1268
[18/Mar/2024 22:42:23] "GET /static/rest_framework/img/grid.png HTTP/1.1" 200 1458
Not Found: /favicon.ico
[18/Mar/2024 22:42:24] "GET /favicon.ico HTTP/1.1" 404 2764
[18/Mar/2024 22:42:39] "GET /website HTTP/1.1" 301 0
[18/Mar/2024 22:42:39] "GET /website/ HTTP/1.1" 200 669
[18/Mar/2024 22:44:44] "GET /website/ HTTP/1.1" 200 669
[18/Mar/2024 22:44:45] "GET /website/ HTTP/1.1" 200 669
/home/ubuntu/djangobackend/djangobackend/settings.py changed, reloading.
Performing system checks...

System check identified no issues (0 silenced).
March 05, 2024 - 03:00:56
Django version 5.0.1, using settings 'djangobackend.settings'
Starting development server at http://0.0.0.0:8000/
Quit the server with CONTROL-C.

Traceback (most recent call last):
  File "/home/ubuntu/.local/lib/python3.10/site-packages/django/core/management/base.py", line 412, in run_from_argv
    self.execute(*args, **cmd_options)
  File "/home/ubuntu/.local/lib/python3.10/site-packages/django/core/management/commands/runserver.py", line 74, in execute
    super().execute(*args, **options)
  File "/home/ubuntu/.local/lib/python3.10/site-packages/django/core/management/base.py", line 458, in execute
    output = self.handle(*args, **options)
  File "/home/ubuntu/.local/lib/python3.10/site-packages/django/core/management/commands/runserver.py", line 81, in handle
    if not settings.DEBUG and not settings.ALLOWED_HOSTS:
  File "/home/ubuntu/.local/lib/python3.10/site-packages/django/conf/__init__.py", line 89, in __getattr__
    self._setup(name)
  File "/home/ubuntu/.local/lib/python3.10/site-packages/django/conf/__init__.py", line 76, in _setup
    self._wrapped = Settings(settings_module)
  File "/home/ubuntu/.local/lib/python3.10/site-packages/django/conf/__init__.py", line 190, in __init__
    mod = importlib.import_module(self.SETTINGS_MODULE)
  File "/usr/lib/python3.10/importlib/__init__.py", line 126, in import_module
    return _bootstrap._gcd_import(name[level:], package, level)
  File "<frozen importlib._bootstrap>", line 1050, in _gcd_import
  File "<frozen importlib._bootstrap>", line 1027, in _find_and_load
  File "<frozen importlib._bootstrap>", line 1006, in _find_and_load_unlocked
  File "<frozen importlib._bootstrap>", line 688, in _load_unlocked
  File "<frozen importlib._bootstrap_external>", line 883, in exec_module
  File "<frozen importlib._bootstrap>", line 241, in _call_with_frames_removed
  File "/home/ubuntu/djangobackend/djangobackend/settings.py", line 29, in <module>
    import watchdog
ModuleNotFoundError: No module named 'watchdog'

During handling of the above exception, another exception occurred:

Traceback (most recent call last):
  File "/home/ubuntu/djangobackend/manage.py", line 22, in <module>
    main()
  File "/home/ubuntu/djangobackend/manage.py", line 18, in main
    execute_from_command_line(sys.argv)
  File "/home/ubuntu/.local/lib/python3.10/site-packages/django/core/management/__init__.py", line 442, in execute_from_command_line
    utility.execute()
  File "/home/ubuntu/.local/lib/python3.10/site-packages/django/core/management/__init__.py", line 436, in execute
    self.fetch_command(subcommand).run_from_argv(self.argv)
  File "/home/ubuntu/.local/lib/python3.10/site-packages/django/core/management/base.py", line 425, in run_from_argv
    connections.close_all()
  File "/home/ubuntu/.local/lib/python3.10/site-packages/django/utils/connection.py", line 84, in close_all
    for conn in self.all(initialized_only=True):
  File "/home/ubuntu/.local/lib/python3.10/site-packages/django/utils/connection.py", line 76, in all
    return [
  File "/home/ubuntu/.local/lib/python3.10/site-packages/django/utils/connection.py", line 73, in __iter__
    return iter(self.settings)
  File "/home/ubuntu/.local/lib/python3.10/site-packages/django/utils/functional.py", line 47, in __get__
    res = instance.__dict__[self.name] = self.func(instance)
  File "/home/ubuntu/.local/lib/python3.10/site-packages/django/utils/connection.py", line 45, in settings
    self._settings = self.configure_settings(self._settings)
  File "/home/ubuntu/.local/lib/python3.10/site-packages/django/db/utils.py", line 148, in configure_settings
    databases = super().configure_settings(databases)
  File "/home/ubuntu/.local/lib/python3.10/site-packages/django/utils/connection.py", line 50, in configure_settings
    settings = getattr(django_settings, self.settings_name)
  File "/home/ubuntu/.local/lib/python3.10/site-packages/django/conf/__init__.py", line 89, in __getattr__
    self._setup(name)
  File "/home/ubuntu/.local/lib/python3.10/site-packages/django/conf/__init__.py", line 76, in _setup
    self._wrapped = Settings(settings_module)
  File "/home/ubuntu/.local/lib/python3.10/site-packages/django/conf/__init__.py", line 190, in __init__
    mod = importlib.import_module(self.SETTINGS_MODULE)
  File "/usr/lib/python3.10/importlib/__init__.py", line 126, in import_module
    return _bootstrap._gcd_import(name[level:], package, level)
  File "<frozen importlib._bootstrap>", line 1050, in _gcd_import
  File "<frozen importlib._bootstrap>", line 1027, in _find_and_load
  File "<frozen importlib._bootstrap>", line 1006, in _find_and_load_unlocked
  File "<frozen importlib._bootstrap>", line 688, in _load_unlocked
  File "<frozen importlib._bootstrap_external>", line 883, in exec_module
  File "<frozen importlib._bootstrap>", line 241, in _call_with_frames_removed
  File "/home/ubuntu/djangobackend/djangobackend/settings.py", line 29, in <module>
    import watchdog
ModuleNotFoundError: No module named 'watchdog'
